WARNING 2019-04-18 07:43:59,147 basehttp 124 "GET /static/register.html HTTP/1.1" 404 1652
WARNING 2019-04-18 07:44:13,308 base 152 Not Found: /templates/register.html
WARNING 2019-04-18 07:44:13,308 basehttp 124 "GET /templates/register.html HTTP/1.1" 404 2000
INFO 2019-04-18 07:50:20,333 basehttp 124 "GET / HTTP/1.1" 200 1716
INFO 2019-04-18 15:56:51,017 basehttp 124 "GET / HTTP/1.1" 200 1714
WARNING 2019-04-18 16:27:03,477 base 152 Not Found: /register/
WARNING 2019-04-18 16:27:03,478 basehttp 124 "GET /register/ HTTP/1.1" 404 2060
INFO 2019-04-18 16:27:36,121 basehttp 124 "GET /register/ HTTP/1.1" 200 3822
INFO 2019-04-18 16:34:58,577 basehttp 124 "GET /register/ HTTP/1.1" 200 3820
INFO 2019-04-18 16:34:59,192 basehttp 124 "GET /register/ HTTP/1.1" 200 3820
INFO 2019-04-18 16:34:59,448 basehttp 124 "GET /register/ HTTP/1.1" 200 3820
INFO 2019-04-18 16:34:59,636 basehttp 124 "GET /register/ HTTP/1.1" 200 3820
INFO 2019-04-18 16:35:41,635 basehttp 124 "GET /register/ HTTP/1.1" 200 3818
INFO 2019-04-18 16:35:41,862 basehttp 124 "GET /register/ HTTP/1.1" 200 3818
INFO 2019-04-18 16:35:42,060 basehttp 124 "GET /register/ HTTP/1.1" 200 3818
INFO 2019-04-18 16:35:42,233 basehttp 124 "GET /register/ HTTP/1.1" 200 3818
INFO 2019-04-18 16:35:44,993 basehttp 124 "GET /register/ HTTP/1.1" 200 3818
INFO 2019-04-20 19:19:12,054 basehttp 124 "GET / HTTP/1.1" 200 25122
INFO 2019-04-20 19:19:12,123 basehttp 124 "GET /static/js/axios-0.18.0.min.js HTTP/1.1" 200 12941
INFO 2019-04-20 19:19:12,123 basehttp 124 "GET /static/js/host.js HTTP/1.1" 200 75
INFO 2019-04-20 19:19:12,124 basehttp 124 "GET /static/images/goods/goods001.jpg HTTP/1.1" 200 5391
INFO 2019-04-20 19:19:12,126 basehttp 124 "GET /static/js/jquery-1.12.4.min.js HTTP/1.1" 200 97163
INFO 2019-04-20 19:19:12,129 basehttp 124 "GET /static/js/vue-2.5.16.js HTTP/1.1" 200 289307
INFO 2019-04-20 19:19:12,147 basehttp 124 "GET /static/js/index.js HTTP/1.1" 200 1727
INFO 2019-04-20 19:19:12,147 basehttp 124 "GET /static/js/slide.js HTTP/1.1" 200 1822
INFO 2019-04-20 19:19:12,160 basehttp 124 "GET /static/images/goods/goods002.jpg HTTP/1.1" 200 5377
INFO 2019-04-20 19:19:12,161 basehttp 124 "GET /static/js/common.js HTTP/1.1" 200 891
INFO 2019-04-20 19:19:12,167 basehttp 124 "GET /static/images/slide01.jpg HTTP/1.1" 200 67813
INFO 2019-04-20 19:19:12,168 basehttp 124 "GET /static/images/slide02.jpg HTTP/1.1" 200 89905
INFO 2019-04-20 19:19:12,192 basehttp 124 "GET /static/images/banner01.jpg HTTP/1.1" 200 23658
INFO 2019-04-20 19:19:12,193 basehttp 124 "GET /static/images/slide03.jpg HTTP/1.1" 200 70152
INFO 2019-04-20 19:19:12,193 basehttp 124 "GET /static/images/goods/goods004.jpg HTTP/1.1" 200 6565
INFO 2019-04-20 19:19:12,194 basehttp 124 "GET /static/images/adv01.jpg HTTP/1.1" 200 39831
INFO 2019-04-20 19:19:12,194 basehttp 124 "GET /static/images/goods/goods003.jpg HTTP/1.1" 200 8579
INFO 2019-04-20 19:19:12,194 basehttp 124 "GET /static/images/slide04.jpg HTTP/1.1" 200 107973
INFO 2019-04-20 19:19:12,199 basehttp 124 "GET /static/images/goods/goods005.jpg HTTP/1.1" 200 7578
INFO 2019-04-20 19:19:12,201 basehttp 124 "GET /static/images/goods/goods008.jpg HTTP/1.1" 200 7072
INFO 2019-04-20 19:19:12,201 basehttp 124 "GET /static/images/banner02.jpg HTTP/1.1" 200 26729
INFO 2019-04-20 19:19:12,202 basehttp 124 "GET /static/images/banner03.jpg HTTP/1.1" 200 22681
INFO 2019-04-20 19:19:12,203 basehttp 124 "GET /static/images/goods/goods009.jpg HTTP/1.1" 200 8738
INFO 2019-04-20 19:19:12,203 basehttp 124 "GET /static/images/icons.png HTTP/1.1" 200 7740
WARNING 2019-04-20 19:19:12,405 base 152 Not Found: /carts/simple/
WARNING 2019-04-20 19:19:12,405 basehttp 124 "GET /carts/simple/ HTTP/1.1" 404 2293
WARNING 2019-04-20 19:19:12,443 base 152 Not Found: /favicon.ico
WARNING 2019-04-20 19:19:12,444 basehttp 124 "GET /favicon.ico HTTP/1.1" 404 2287
WARNING 2019-04-20 19:19:18,976 base 152 Not Found: /register.html
WARNING 2019-04-20 19:19:18,977 basehttp 124 "GET /register.html HTTP/1.1" 404 2293
INFO 2019-04-20 19:19:34,766 basehttp 124 "GET /register/ HTTP/1.1" 200 4799
WARNING 2019-04-20 19:19:34,787 base 152 Not Found: /register/images/pic_code.jpg
WARNING 2019-04-20 19:19:34,788 basehttp 124 "GET /register/images/pic_code.jpg HTTP/1.1" 404 2338
WARNING 2019-04-20 19:19:34,891 base 152 Not Found: /register/images/pic_code.jpg
WARNING 2019-04-20 19:19:34,891 basehttp 124 "GET /register/images/pic_code.jpg HTTP/1.1" 404 2338
WARNING 2019-04-20 19:19:43,912 base 152 Not Found: /usernames/asdfd/count/
WARNING 2019-04-20 19:19:43,913 basehttp 124 "GET /usernames/asdfd/count/ HTTP/1.1" 404 2320
WARNING 2019-04-20 19:19:46,171 base 152 Not Found: /usernames/asdfd/count/
WARNING 2019-04-20 19:19:46,171 basehttp 124 "GET /usernames/asdfd/count/ HTTP/1.1" 404 2320
INFO 2019-04-20 19:58:33,472 basehttp 124 "GET /register/ HTTP/1.1" 200 4939
ERROR 2019-04-20 19:58:33,530 exception 135 Internal Server Error: /image_codes/b5af8550-68fc-4369-9148-b1b5934ea366/
Traceback (most recent call last):
  File "/Users/c/Envs/mdd_mall/lib/python3.7/site-packages/redis/connection.py", line 492, in connect
    sock = self._connect()
  File "/Users/c/Envs/mdd_mall/lib/python3.7/site-packages/redis/connection.py", line 550, in _connect
    raise err
  File "/Users/c/Envs/mdd_mall/lib/python3.7/site-packages/redis/connection.py", line 538, in _connect
    sock.connect(socket_address)
ConnectionRefusedError: [Errno 61] Connection refused

During handling of the above exception, another exception occurred:

Traceback (most recent call last):
  File "/Users/c/Envs/mdd_mall/lib/python3.7/site-packages/django/core/handlers/exception.py", line 41, in inner
    response = get_response(request)
  File "/Users/c/Envs/mdd_mall/lib/python3.7/site-packages/django/core/handlers/base.py", line 187, in _get_response
    response = self.process_exception_by_middleware(e, request)
  File "/Users/c/Envs/mdd_mall/lib/python3.7/site-packages/django/core/handlers/base.py", line 185, in _get_response
    response = wrapped_callback(request, *callback_args, **callback_kwargs)
  File "/Users/c/Envs/mdd_mall/lib/python3.7/site-packages/django/views/generic/base.py", line 68, in view
    return self.dispatch(request, *args, **kwargs)
  File "/Users/c/Envs/mdd_mall/lib/python3.7/site-packages/django/views/generic/base.py", line 88, in dispatch
    return handler(request, *args, **kwargs)
  File "/Users/c/Documents/mddproject/mddproject/mdd_mall/mdd_mall/apps/verifications/views.py", line 16, in get
    redis_conn.setex('img_%s'%uuid,300,text)
  File "/Users/c/Envs/mdd_mall/lib/python3.7/site-packages/redis/client.py", line 1472, in setex
    return self.execute_command('SETEX', name, time, value)
  File "/Users/c/Envs/mdd_mall/lib/python3.7/site-packages/redis/client.py", line 772, in execute_command
    connection = pool.get_connection(command_name, **options)
  File "/Users/c/Envs/mdd_mall/lib/python3.7/site-packages/redis/connection.py", line 994, in get_connection
    connection.connect()
  File "/Users/c/Envs/mdd_mall/lib/python3.7/site-packages/redis/connection.py", line 497, in connect
    raise ConnectionError(self._error_message(e))
redis.exceptions.ConnectionError: Error 61 connecting to 127.0.0.1:6379. Connection refused.
ERROR 2019-04-20 19:58:33,577 basehttp 124 "GET /image_codes/b5af8550-68fc-4369-9148-b1b5934ea366/ HTTP/1.1" 500 111590
INFO 2019-04-20 19:58:36,034 basehttp 124 "GET /register/ HTTP/1.1" 200 4939
ERROR 2019-04-20 19:58:36,083 exception 135 Internal Server Error: /image_codes/2c461861-9f94-4f11-afad-11f9e0f80581/
Traceback (most recent call last):
  File "/Users/c/Envs/mdd_mall/lib/python3.7/site-packages/redis/connection.py", line 492, in connect
    sock = self._connect()
  File "/Users/c/Envs/mdd_mall/lib/python3.7/site-packages/redis/connection.py", line 550, in _connect
    raise err
  File "/Users/c/Envs/mdd_mall/lib/python3.7/site-packages/redis/connection.py", line 538, in _connect
    sock.connect(socket_address)
ConnectionRefusedError: [Errno 61] Connection refused

During handling of the above exception, another exception occurred:

Traceback (most recent call last):
  File "/Users/c/Envs/mdd_mall/lib/python3.7/site-packages/django/core/handlers/exception.py", line 41, in inner
    response = get_response(request)
  File "/Users/c/Envs/mdd_mall/lib/python3.7/site-packages/django/core/handlers/base.py", line 187, in _get_response
    response = self.process_exception_by_middleware(e, request)
  File "/Users/c/Envs/mdd_mall/lib/python3.7/site-packages/django/core/handlers/base.py", line 185, in _get_response
    response = wrapped_callback(request, *callback_args, **callback_kwargs)
  File "/Users/c/Envs/mdd_mall/lib/python3.7/site-packages/django/views/generic/base.py", line 68, in view
    return self.dispatch(request, *args, **kwargs)
  File "/Users/c/Envs/mdd_mall/lib/python3.7/site-packages/django/views/generic/base.py", line 88, in dispatch
    return handler(request, *args, **kwargs)
  File "/Users/c/Documents/mddproject/mddproject/mdd_mall/mdd_mall/apps/verifications/views.py", line 16, in get
    redis_conn.setex('img_%s'%uuid,300,text)
  File "/Users/c/Envs/mdd_mall/lib/python3.7/site-packages/redis/client.py", line 1472, in setex
    return self.execute_command('SETEX', name, time, value)
  File "/Users/c/Envs/mdd_mall/lib/python3.7/site-packages/redis/client.py", line 772, in execute_command
    connection = pool.get_connection(command_name, **options)
  File "/Users/c/Envs/mdd_mall/lib/python3.7/site-packages/redis/connection.py", line 994, in get_connection
    connection.connect()
  File "/Users/c/Envs/mdd_mall/lib/python3.7/site-packages/redis/connection.py", line 497, in connect
    raise ConnectionError(self._error_message(e))
redis.exceptions.ConnectionError: Error 61 connecting to 127.0.0.1:6379. Connection refused.
ERROR 2019-04-20 19:58:36,122 basehttp 124 "GET /image_codes/2c461861-9f94-4f11-afad-11f9e0f80581/ HTTP/1.1" 500 111343
INFO 2019-04-20 19:58:45,089 basehttp 124 "GET /register/ HTTP/1.1" 200 4939
ERROR 2019-04-20 19:58:45,126 exception 135 Internal Server Error: /image_codes/5bd67e41-479f-49a9-b666-bdbf34ba2d93/
Traceback (most recent call last):
  File "/Users/c/Envs/mdd_mall/lib/python3.7/site-packages/redis/connection.py", line 492, in connect
    sock = self._connect()
  File "/Users/c/Envs/mdd_mall/lib/python3.7/site-packages/redis/connection.py", line 550, in _connect
    raise err
  File "/Users/c/Envs/mdd_mall/lib/python3.7/site-packages/redis/connection.py", line 538, in _connect
    sock.connect(socket_address)
ConnectionRefusedError: [Errno 61] Connection refused

During handling of the above exception, another exception occurred:

Traceback (most recent call last):
  File "/Users/c/Envs/mdd_mall/lib/python3.7/site-packages/django/core/handlers/exception.py", line 41, in inner
    response = get_response(request)
  File "/Users/c/Envs/mdd_mall/lib/python3.7/site-packages/django/core/handlers/base.py", line 187, in _get_response
    response = self.process_exception_by_middleware(e, request)
  File "/Users/c/Envs/mdd_mall/lib/python3.7/site-packages/django/core/handlers/base.py", line 185, in _get_response
    response = wrapped_callback(request, *callback_args, **callback_kwargs)
  File "/Users/c/Envs/mdd_mall/lib/python3.7/site-packages/django/views/generic/base.py", line 68, in view
    return self.dispatch(request, *args, **kwargs)
  File "/Users/c/Envs/mdd_mall/lib/python3.7/site-packages/django/views/generic/base.py", line 88, in dispatch
    return handler(request, *args, **kwargs)
  File "/Users/c/Documents/mddproject/mddproject/mdd_mall/mdd_mall/apps/verifications/views.py", line 16, in get
    redis_conn.setex('img_%s'%uuid,300,text)
  File "/Users/c/Envs/mdd_mall/lib/python3.7/site-packages/redis/client.py", line 1472, in setex
    return self.execute_command('SETEX', name, time, value)
  File "/Users/c/Envs/mdd_mall/lib/python3.7/site-packages/redis/client.py", line 772, in execute_command
    connection = pool.get_connection(command_name, **options)
  File "/Users/c/Envs/mdd_mall/lib/python3.7/site-packages/redis/connection.py", line 994, in get_connection
    connection.connect()
  File "/Users/c/Envs/mdd_mall/lib/python3.7/site-packages/redis/connection.py", line 497, in connect
    raise ConnectionError(self._error_message(e))
redis.exceptions.ConnectionError: Error 61 connecting to 127.0.0.1:6379. Connection refused.
ERROR 2019-04-20 19:58:45,171 basehttp 124 "GET /image_codes/5bd67e41-479f-49a9-b666-bdbf34ba2d93/ HTTP/1.1" 500 111337
INFO 2019-04-20 20:00:22,770 basehttp 124 "GET /register/ HTTP/1.1" 200 4939
INFO 2019-04-20 20:00:22,817 basehttp 124 "GET /image_codes/349141f0-9dba-41c5-bea8-4d468455c880/ HTTP/1.1" 200 3103
INFO 2019-04-20 20:00:24,567 basehttp 124 "GET /image_codes/c45f43f2-0848-47d3-ae95-5b4d2eb65264/ HTTP/1.1" 200 3229
INFO 2019-04-20 20:00:24,848 basehttp 124 "GET /image_codes/04a12905-2093-4c44-b56b-2ec8b38b6071/ HTTP/1.1" 200 2966
INFO 2019-04-20 20:00:24,996 basehttp 124 "GET /image_codes/ae56c7dc-eb7e-4e74-889e-86eafa78439b/ HTTP/1.1" 200 3254
INFO 2019-04-20 20:00:25,150 basehttp 124 "GET /image_codes/4b9c7974-0cca-430b-a184-65bda7d7e51d/ HTTP/1.1" 200 3243
INFO 2019-04-20 20:00:25,302 basehttp 124 "GET /image_codes/0f4c7dc5-8b1f-4bff-afd8-73679513f199/ HTTP/1.1" 200 3369
INFO 2019-04-20 20:00:25,433 basehttp 124 "GET /image_codes/54fd210b-fef4-43b9-af67-444ec0e04860/ HTTP/1.1" 200 2972
INFO 2019-04-20 20:01:10,751 basehttp 124 "GET /image_codes/ff55dd52-ef84-4cd8-908c-6a4f3a2590e9/ HTTP/1.1" 200 3166
INFO 2019-04-20 20:15:31,068 basehttp 124 "GET /register/ HTTP/1.1" 200 4939
INFO 2019-04-20 20:15:31,116 basehttp 124 "GET /image_codes/ab9c4c1e-0a70-42fa-a650-cc66a712937c/ HTTP/1.1" 200 2883
INFO 2019-04-20 20:15:31,824 basehttp 124 "GET /register/ HTTP/1.1" 200 4939
INFO 2019-04-20 20:15:31,871 basehttp 124 "GET /image_codes/d6ff1a51-01de-4960-9946-fe9e5e3f888a/ HTTP/1.1" 200 3433
INFO 2019-04-20 20:15:32,431 basehttp 124 "GET /register/ HTTP/1.1" 200 4939
INFO 2019-04-20 20:15:32,473 basehttp 124 "GET /image_codes/b6f8e5c5-4594-4f51-9fb7-9035e6c58e95/ HTTP/1.1" 200 3456
INFO 2019-04-20 20:15:33,217 basehttp 124 "GET /register/ HTTP/1.1" 200 4939
INFO 2019-04-20 20:15:33,263 basehttp 124 "GET /image_codes/deb67a47-b481-403a-8db1-780c9eaec523/ HTTP/1.1" 200 3111
INFO 2019-04-20 20:15:39,789 basehttp 124 "GET /register/ HTTP/1.1" 200 4939
INFO 2019-04-20 20:15:39,834 basehttp 124 "GET /image_codes/4aee2581-577d-4e63-a669-2fffb6f02d57/ HTTP/1.1" 200 2817
INFO 2019-04-20 20:15:52,466 basehttp 124 "GET /register/ HTTP/1.1" 200 4939
INFO 2019-04-20 20:15:52,509 basehttp 124 "GET /image_codes/551cafb9-4017-4172-a6b0-2222594de3fa/ HTTP/1.1" 200 3461
INFO 2019-04-20 20:16:33,831 basehttp 124 "GET /register/ HTTP/1.1" 200 4998
INFO 2019-04-20 20:16:33,880 basehttp 124 "GET /image_codes/90606313-17ed-4b36-97e6-3c2d51609621/ HTTP/1.1" 200 2906
INFO 2019-04-20 20:16:34,465 basehttp 124 "GET /register/ HTTP/1.1" 200 4998
INFO 2019-04-20 20:16:34,512 basehttp 124 "GET /image_codes/7abdbd22-cf14-4bc3-9d01-9890e571c96a/ HTTP/1.1" 200 3468
INFO 2019-04-20 20:31:20,345 basehttp 124 "GET /register/ HTTP/1.1" 200 4998
ERROR 2019-04-20 20:31:20,391 exception 135 Internal Server Error: /image_codes/acf21b2f-228b-49c6-9f5e-fc003fadf871/
Traceback (most recent call last):
  File "/Users/c/Envs/mdd_mall/lib/python3.7/site-packages/redis/connection.py", line 492, in connect
    sock = self._connect()
  File "/Users/c/Envs/mdd_mall/lib/python3.7/site-packages/redis/connection.py", line 550, in _connect
    raise err
  File "/Users/c/Envs/mdd_mall/lib/python3.7/site-packages/redis/connection.py", line 538, in _connect
    sock.connect(socket_address)
ConnectionRefusedError: [Errno 61] Connection refused

During handling of the above exception, another exception occurred:

Traceback (most recent call last):
  File "/Users/c/Envs/mdd_mall/lib/python3.7/site-packages/django/core/handlers/exception.py", line 41, in inner
    response = get_response(request)
  File "/Users/c/Envs/mdd_mall/lib/python3.7/site-packages/django/core/handlers/base.py", line 187, in _get_response
    response = self.process_exception_by_middleware(e, request)
  File "/Users/c/Envs/mdd_mall/lib/python3.7/site-packages/django/core/handlers/base.py", line 185, in _get_response
    response = wrapped_callback(request, *callback_args, **callback_kwargs)
  File "/Users/c/Envs/mdd_mall/lib/python3.7/site-packages/django/views/generic/base.py", line 68, in view
    return self.dispatch(request, *args, **kwargs)
  File "/Users/c/Envs/mdd_mall/lib/python3.7/site-packages/django/views/generic/base.py", line 88, in dispatch
    return handler(request, *args, **kwargs)
  File "/Users/c/Documents/mddproject/mddproject/mdd_mall/mdd_mall/apps/verifications/views.py", line 16, in get
    redis_conn.setex('img_%s'%uuid,300,text)
  File "/Users/c/Envs/mdd_mall/lib/python3.7/site-packages/redis/client.py", line 1472, in setex
    return self.execute_command('SETEX', name, time, value)
  File "/Users/c/Envs/mdd_mall/lib/python3.7/site-packages/redis/client.py", line 772, in execute_command
    connection = pool.get_connection(command_name, **options)
  File "/Users/c/Envs/mdd_mall/lib/python3.7/site-packages/redis/connection.py", line 994, in get_connection
    connection.connect()
  File "/Users/c/Envs/mdd_mall/lib/python3.7/site-packages/redis/connection.py", line 497, in connect
    raise ConnectionError(self._error_message(e))
redis.exceptions.ConnectionError: Error 61 connecting to 127.0.0.1:6379. Connection refused.
ERROR 2019-04-20 20:31:20,432 basehttp 124 "GET /image_codes/acf21b2f-228b-49c6-9f5e-fc003fadf871/ HTTP/1.1" 500 111232
INFO 2019-04-20 20:31:27,784 basehttp 124 "GET / HTTP/1.1" 200 25122
WARNING 2019-04-20 20:31:27,909 base 152 Not Found: /carts/simple/
WARNING 2019-04-20 20:31:27,909 basehttp 124 "GET /carts/simple/ HTTP/1.1" 404 2878
INFO 2019-04-20 20:31:30,404 basehttp 124 "GET /static/cart.html HTTP/1.1" 200 4598
INFO 2019-04-20 20:31:30,417 basehttp 124 "GET /static/js/cart.js HTTP/1.1" 200 18210
INFO 2019-04-21 15:07:39,629 basehttp 124 "GET / HTTP/1.1" 200 25122
INFO 2019-04-21 15:07:39,737 basehttp 124 "GET /static/js/jquery-1.12.4.min.js HTTP/1.1" 200 97163
INFO 2019-04-21 15:07:39,739 basehttp 124 "GET /static/js/vue-2.5.16.js HTTP/1.1" 200 289307
INFO 2019-04-21 15:07:39,795 basehttp 124 "GET /static/images/slide02.jpg HTTP/1.1" 200 89905
INFO 2019-04-21 15:07:39,795 basehttp 124 "GET /static/images/slide04.jpg HTTP/1.1" 200 107973
WARNING 2019-04-21 15:07:39,973 base 152 Not Found: /carts/simple/
WARNING 2019-04-21 15:07:39,974 basehttp 124 "GET /carts/simple/ HTTP/1.1" 404 2878
WARNING 2019-04-21 15:07:40,010 base 152 Not Found: /favicon.ico
WARNING 2019-04-21 15:07:40,010 basehttp 124 "GET /favicon.ico HTTP/1.1" 404 2872
INFO 2019-04-21 15:07:48,122 basehttp 124 "GET /register/ HTTP/1.1" 200 4998
ERROR 2019-04-21 15:07:48,261 exception 135 Internal Server Error: /image_codes/6a439ec9-3b55-49b2-bda5-03efbecb67f6/
Traceback (most recent call last):
  File "/Users/c/Envs/mdd_mall/lib/python3.7/site-packages/redis/connection.py", line 492, in connect
    sock = self._connect()
  File "/Users/c/Envs/mdd_mall/lib/python3.7/site-packages/redis/connection.py", line 550, in _connect
    raise err
  File "/Users/c/Envs/mdd_mall/lib/python3.7/site-packages/redis/connection.py", line 538, in _connect
    sock.connect(socket_address)
ConnectionRefusedError: [Errno 61] Connection refused

During handling of the above exception, another exception occurred:

Traceback (most recent call last):
  File "/Users/c/Envs/mdd_mall/lib/python3.7/site-packages/django/core/handlers/exception.py", line 41, in inner
    response = get_response(request)
  File "/Users/c/Envs/mdd_mall/lib/python3.7/site-packages/django/core/handlers/base.py", line 187, in _get_response
    response = self.process_exception_by_middleware(e, request)
  File "/Users/c/Envs/mdd_mall/lib/python3.7/site-packages/django/core/handlers/base.py", line 185, in _get_response
    response = wrapped_callback(request, *callback_args, **callback_kwargs)
  File "/Users/c/Envs/mdd_mall/lib/python3.7/site-packages/django/views/generic/base.py", line 68, in view
    return self.dispatch(request, *args, **kwargs)
  File "/Users/c/Envs/mdd_mall/lib/python3.7/site-packages/django/views/generic/base.py", line 88, in dispatch
    return handler(request, *args, **kwargs)
  File "/Users/c/Documents/mddproject/mddproject/mdd_mall/mdd_mall/apps/verifications/views.py", line 16, in get
    redis_conn.setex('img_%s'%uuid,300,text)
  File "/Users/c/Envs/mdd_mall/lib/python3.7/site-packages/redis/client.py", line 1472, in setex
    return self.execute_command('SETEX', name, time, value)
  File "/Users/c/Envs/mdd_mall/lib/python3.7/site-packages/redis/client.py", line 772, in execute_command
    connection = pool.get_connection(command_name, **options)
  File "/Users/c/Envs/mdd_mall/lib/python3.7/site-packages/redis/connection.py", line 994, in get_connection
    connection.connect()
  File "/Users/c/Envs/mdd_mall/lib/python3.7/site-packages/redis/connection.py", line 497, in connect
    raise ConnectionError(self._error_message(e))
redis.exceptions.ConnectionError: Error 61 connecting to 127.0.0.1:6379. Connection refused.
ERROR 2019-04-21 15:07:48,306 basehttp 124 "GET /image_codes/6a439ec9-3b55-49b2-bda5-03efbecb67f6/ HTTP/1.1" 500 111251
INFO 2019-04-21 15:07:56,052 basehttp 124 "GET /register/ HTTP/1.1" 200 4998
INFO 2019-04-21 15:07:56,110 basehttp 124 "GET /image_codes/74558abe-0c64-4461-b1a7-07a03a934cdc/ HTTP/1.1" 200 2581
INFO 2019-04-21 15:07:57,494 basehttp 124 "GET /register/ HTTP/1.1" 200 4998
INFO 2019-04-21 15:07:57,545 basehttp 124 "GET /image_codes/32cc3d6b-15dc-4c77-bd59-7b440066623d/ HTTP/1.1" 200 3088
INFO 2019-04-21 15:08:50,080 basehttp 124 "GET /register/ HTTP/1.1" 200 4948
INFO 2019-04-21 15:08:50,130 basehttp 124 "GET /image_codes/95733244-24c7-47b4-b859-563d2ef76695/ HTTP/1.1" 200 3158
INFO 2019-04-21 15:40:05,183 basehttp 124 "GET /register/ HTTP/1.1" 200 5103
INFO 2019-04-21 15:40:05,240 basehttp 124 "GET /image_codes/aded2eb0-6082-4b8c-9135-965cacc08ed3/ HTTP/1.1" 200 3341
INFO 2019-04-21 15:40:55,886 basehttp 124 "GET /usernames/mmmmm/count/ HTTP/1.1" 200 41
INFO 2019-04-21 15:41:09,363 basehttp 124 "GET /mobiles/13818510759/count/ HTTP/1.1" 200 41
INFO 2019-04-21 15:41:15,150 basehttp 124 "GET /mobiles/13818510725/count/ HTTP/1.1" 200 41
INFO 2019-04-21 15:41:20,367 basehttp 124 "GET /image_codes/e5f6535d-e4d1-44e9-b657-52da08f623ea/ HTTP/1.1" 200 3095
INFO 2019-04-21 15:41:30,074 basehttp 124 "GET /sms_codes/13818510725/?image_code=gggg&image_code_id=e5f6535d-e4d1-44e9-b657-52da08f623ea HTTP/1.1" 200 72
INFO 2019-04-21 15:41:30,076 basehttp 124 "GET /mobiles/13818510725/count/ HTTP/1.1" 200 41
INFO 2019-04-21 15:41:30,085 basehttp 124 "GET /image_codes/3852e16a-c8f9-4827-88c9-379781c9c5c8/ HTTP/1.1" 200 3049
INFO 2019-04-21 15:41:37,114 basehttp 124 "GET /sms_codes/13818510725/?image_code=gggg&image_code_id=3852e16a-c8f9-4827-88c9-379781c9c5c8 HTTP/1.1" 200 72
INFO 2019-04-21 15:41:37,117 basehttp 124 "GET /mobiles/13818510725/count/ HTTP/1.1" 200 41
INFO 2019-04-21 15:41:37,128 basehttp 124 "GET /image_codes/b092ec16-87ed-4d06-a67c-6973181f4200/ HTTP/1.1" 200 3245
INFO 2019-04-21 15:42:11,065 basehttp 124 "GET /register/ HTTP/1.1" 200 5103
INFO 2019-04-21 15:42:11,299 basehttp 124 "GET /image_codes/a361d0ec-c465-4abd-a0c9-abfbe3b48d3d/ HTTP/1.1" 200 3608
INFO 2019-04-21 15:42:13,612 basehttp 124 "GET /usernames/admin/count/ HTTP/1.1" 200 41
INFO 2019-04-21 15:42:19,510 basehttp 124 "GET /mobiles/13818510759/count/ HTTP/1.1" 200 41
INFO 2019-04-21 15:42:24,092 basehttp 124 "GET /sms_codes/13818510759/?image_code=2222&image_code_id=a361d0ec-c465-4abd-a0c9-abfbe3b48d3d HTTP/1.1" 200 72
INFO 2019-04-21 15:42:24,095 basehttp 124 "GET /mobiles/13818510759/count/ HTTP/1.1" 200 41
INFO 2019-04-21 15:42:24,104 basehttp 124 "GET /image_codes/68357e7f-d542-445f-a682-80fd93100482/ HTTP/1.1" 200 3158
INFO 2019-04-21 15:42:36,582 basehttp 124 "GET /image_codes/cab035f2-8f20-490a-ac7f-c3c85e2cc57c/ HTTP/1.1" 200 3180
INFO 2019-04-21 15:42:40,303 basehttp 124 "GET /sms_codes/13818510759/?image_code=2222&image_code_id=cab035f2-8f20-490a-ac7f-c3c85e2cc57c HTTP/1.1" 200 72
INFO 2019-04-21 15:42:40,307 basehttp 124 "GET /mobiles/13818510759/count/ HTTP/1.1" 200 41
INFO 2019-04-21 15:42:40,315 basehttp 124 "GET /image_codes/70f01d80-123d-43f7-a3c7-2e6347cdc127/ HTTP/1.1" 200 2937
INFO 2019-04-21 15:44:42,059 basehttp 124 "GET /register/ HTTP/1.1" 200 5103
INFO 2019-04-21 15:44:42,111 basehttp 124 "GET /image_codes/bedd5724-c4b3-49cb-9e52-ce8604f30918/ HTTP/1.1" 200 3065
INFO 2019-04-21 15:44:43,152 basehttp 124 "GET /register/ HTTP/1.1" 200 5103
INFO 2019-04-21 15:44:43,204 basehttp 124 "GET /image_codes/444e7408-090e-4f61-90fb-7efdc6ac60e2/ HTTP/1.1" 200 2596
INFO 2019-04-21 15:44:47,406 basehttp 124 "GET /usernames/admin/count/ HTTP/1.1" 200 41
INFO 2019-04-21 15:44:56,012 basehttp 124 "GET /mobiles/13818510759/count/ HTTP/1.1" 200 41
INFO 2019-04-21 15:44:57,182 basehttp 124 "GET /image_codes/4e11d354-c393-4b2d-8198-93fc5810909b/ HTTP/1.1" 200 3052
INFO 2019-04-21 15:45:00,886 basehttp 124 "GET /sms_codes/13818510759/?image_code=aaaa&image_code_id=4e11d354-c393-4b2d-8198-93fc5810909b HTTP/1.1" 200 60
INFO 2019-04-21 15:45:00,889 basehttp 124 "GET /mobiles/13818510759/count/ HTTP/1.1" 200 41
INFO 2019-04-21 15:45:00,898 basehttp 124 "GET /image_codes/82a9a4f8-a204-4c29-b53b-52b60ff35aee/ HTTP/1.1" 200 2999
INFO 2019-04-21 15:45:05,667 basehttp 124 "GET /sms_codes/13818510759/?image_code=95cl&image_code_id=82a9a4f8-a204-4c29-b53b-52b60ff35aee HTTP/1.1" 200 60
INFO 2019-04-21 15:45:05,670 basehttp 124 "GET /mobiles/13818510759/count/ HTTP/1.1" 200 41
INFO 2019-04-21 15:45:05,680 basehttp 124 "GET /image_codes/9972568d-9537-4c84-a5d6-bb0ff100697c/ HTTP/1.1" 200 2940
INFO 2019-04-21 15:45:13,790 basehttp 124 "GET /sms_codes/13818510759/?image_code=adxo&image_code_id=9972568d-9537-4c84-a5d6-bb0ff100697c HTTP/1.1" 200 60
INFO 2019-04-21 15:45:13,793 basehttp 124 "GET /mobiles/13818510759/count/ HTTP/1.1" 200 41
INFO 2019-04-21 15:45:13,803 basehttp 124 "GET /image_codes/33c36a74-f37b-46f1-8b62-100249d71595/ HTTP/1.1" 200 3762
INFO 2019-04-21 15:45:18,470 basehttp 124 "GET /sms_codes/13818510759/?image_code=vrnp&image_code_id=33c36a74-f37b-46f1-8b62-100249d71595 HTTP/1.1" 200 60
INFO 2019-04-21 15:45:18,474 basehttp 124 "GET /mobiles/13818510759/count/ HTTP/1.1" 200 41
INFO 2019-04-21 15:45:18,483 basehttp 124 "GET /image_codes/4a35ccf2-f11e-4d98-b4d6-141509fef3f6/ HTTP/1.1" 200 3214
INFO 2019-04-21 15:45:44,795 basehttp 124 "GET /register/ HTTP/1.1" 200 5103
INFO 2019-04-21 15:45:47,136 basehttp 124 "GET /register/ HTTP/1.1" 200 5103
INFO 2019-04-21 15:45:47,182 basehttp 124 "GET /image_codes/f27a4ea1-1204-4c54-9120-7cef20aef9d4/ HTTP/1.1" 200 3272
INFO 2019-04-21 15:45:48,738 basehttp 124 "GET /usernames/admin/count/ HTTP/1.1" 200 41
INFO 2019-04-21 15:45:52,583 basehttp 124 "GET /mobiles/13818510759/count/ HTTP/1.1" 200 41
INFO 2019-04-21 15:45:55,891 basehttp 124 "GET /image_codes/231aa21b-3494-4fb4-86af-ff5b8074ba6b/ HTTP/1.1" 200 3086
INFO 2019-04-21 15:46:00,069 views 48 574642
INFO 2019-04-21 15:46:00,069 basehttp 124 "GET /sms_codes/13818510759/?image_code=qhts&image_code_id=231aa21b-3494-4fb4-86af-ff5b8074ba6b HTTP/1.1" 200 29
INFO 2019-04-21 15:46:00,072 basehttp 124 "GET /mobiles/13818510759/count/ HTTP/1.1" 200 41
INFO 2019-04-21 15:48:28,200 basehttp 124 "GET /register/ HTTP/1.1" 200 5287
INFO 2019-04-21 15:48:28,247 basehttp 124 "GET /image_codes/51df2bf2-c081-4f8e-9d2d-cdad8cb34bc4/ HTTP/1.1" 200 3113
INFO 2019-04-21 15:48:28,583 basehttp 124 "GET /register/ HTTP/1.1" 200 5287
INFO 2019-04-21 15:48:28,630 basehttp 124 "GET /image_codes/fd12d03b-d1cd-443b-be0e-8561f70b501e/ HTTP/1.1" 200 3503
INFO 2019-04-21 15:48:28,779 basehttp 124 "GET /register/ HTTP/1.1" 200 5287
INFO 2019-04-21 15:48:28,831 basehttp 124 "GET /image_codes/1739e37f-e8f6-41f2-8f6f-d694e817dbeb/ HTTP/1.1" 200 3124
INFO 2019-04-21 15:48:28,958 basehttp 124 "GET /register/ HTTP/1.1" 200 5287
INFO 2019-04-21 15:48:29,000 basehttp 124 "GET /image_codes/ec20e993-08eb-4ac3-9caa-d61b28c10f16/ HTTP/1.1" 200 3099
INFO 2019-04-21 15:53:56,475 basehttp 124 "GET /register/ HTTP/1.1" 200 5287
INFO 2019-04-21 15:53:56,527 basehttp 124 "GET /image_codes/2627388f-2890-44a9-abc5-cff37ce61338/ HTTP/1.1" 200 2897
WARNING 2019-04-21 15:53:58,548 basehttp 124 "POST /register/ HTTP/1.1" 403 18
INFO 2019-04-21 15:54:03,180 basehttp 124 "GET /image_codes/1938cfb3-4e9f-4828-bb63-59c3289e842a/ HTTP/1.1" 200 3348
INFO 2019-04-21 16:11:59,729 basehttp 124 "GET /register/ HTTP/1.1" 200 5287
INFO 2019-04-21 16:11:59,782 basehttp 124 "GET /image_codes/6bc795e3-7785-431c-9676-838c357bfcf8/ HTTP/1.1" 200 2975
INFO 2019-04-21 16:12:00,857 basehttp 124 "GET /register/ HTTP/1.1" 200 5287
INFO 2019-04-21 16:12:00,917 basehttp 124 "GET /image_codes/9bb1af3d-3321-4899-9cf8-082f6b6b7653/ HTTP/1.1" 200 3437
INFO 2019-04-21 16:12:01,032 basehttp 124 "GET /register/ HTTP/1.1" 200 5287
INFO 2019-04-21 16:12:01,087 basehttp 124 "GET /image_codes/46da782a-b0f9-4189-8b3c-74060c27dac6/ HTTP/1.1" 200 3182
INFO 2019-04-21 16:12:01,200 basehttp 124 "GET /register/ HTTP/1.1" 200 5287
INFO 2019-04-21 16:12:01,250 basehttp 124 "GET /image_codes/d481e6f5-1ad9-4147-8c19-ad69157f21fd/ HTTP/1.1" 200 3028
INFO 2019-04-21 16:12:01,342 basehttp 124 "GET /register/ HTTP/1.1" 200 5287
INFO 2019-04-21 16:12:01,389 basehttp 124 "GET /image_codes/49cf1e8c-1edb-4321-92b9-e946dad00edc/ HTTP/1.1" 200 3672
INFO 2019-04-21 16:12:01,471 basehttp 124 "GET /register/ HTTP/1.1" 200 5287
INFO 2019-04-21 16:12:01,515 basehttp 124 "GET /image_codes/75bc971a-6a6a-4457-b9ca-be3a0870bbb5/ HTTP/1.1" 200 3182
INFO 2019-04-21 16:12:03,987 basehttp 124 "GET /usernames/admin/count/ HTTP/1.1" 200 41
INFO 2019-04-21 16:12:07,769 basehttp 124 "GET /mobiles/13818510759/count/ HTTP/1.1" 200 41
INFO 2019-04-21 16:13:02,865 basehttp 124 "GET /image_codes/dd60779d-6cac-470f-9b0f-a26edd963ff5/ HTTP/1.1" 200 3318
INFO 2019-04-21 16:13:02,987 basehttp 124 "GET /image_codes/12068338-a6a0-45fa-82b7-b7514482c2da/ HTTP/1.1" 200 3133
ERROR 2019-04-21 16:13:06,102 exception 135 Internal Server Error: /sms_codes/13818510759/
Traceback (most recent call last):
  File "/Users/c/Envs/mdd_mall/lib/python3.7/site-packages/django/core/handlers/exception.py", line 41, in inner
    response = get_response(request)
  File "/Users/c/Envs/mdd_mall/lib/python3.7/site-packages/django/core/handlers/base.py", line 187, in _get_response
    response = self.process_exception_by_middleware(e, request)
  File "/Users/c/Envs/mdd_mall/lib/python3.7/site-packages/django/core/handlers/base.py", line 185, in _get_response
    response = wrapped_callback(request, *callback_args, **callback_kwargs)
  File "/Users/c/Envs/mdd_mall/lib/python3.7/site-packages/django/views/generic/base.py", line 68, in view
    return self.dispatch(request, *args, **kwargs)
  File "/Users/c/Envs/mdd_mall/lib/python3.7/site-packages/django/views/generic/base.py", line 88, in dispatch
    return handler(request, *args, **kwargs)
  File "/Users/c/Documents/mddproject/mddproject/mdd_mall/mdd_mall/apps/verifications/views.py", line 35, in get
    redis_flag = redis_conn.get(mobile).decode()
AttributeError: 'NoneType' object has no attribute 'decode'
INFO 2019-04-21 16:13:06,115 basehttp 124 "GET /mobiles/13818510759/count/ HTTP/1.1" 200 41
ERROR 2019-04-21 16:13:06,134 basehttp 124 "GET /sms_codes/13818510759/?image_code=khml&image_code_id=12068338-a6a0-45fa-82b7-b7514482c2da HTTP/1.1" 500 77532
INFO 2019-04-21 16:13:44,348 basehttp 124 "GET /register/ HTTP/1.1" 200 5287
INFO 2019-04-21 16:13:44,401 basehttp 124 "GET /image_codes/a2f59218-445c-4ff6-8da6-77339248ba37/ HTTP/1.1" 200 3133
INFO 2019-04-21 16:13:45,971 basehttp 124 "GET /usernames/admin/count/ HTTP/1.1" 200 41
INFO 2019-04-21 16:13:51,331 basehttp 124 "GET /mobiles/13818510759/count/ HTTP/1.1" 200 41
INFO 2019-04-21 16:13:56,638 views 52 731045
INFO 2019-04-21 16:13:56,639 basehttp 124 "GET /sms_codes/13818510759/?image_code=7mhb&image_code_id=a2f59218-445c-4ff6-8da6-77339248ba37 HTTP/1.1" 200 29
INFO 2019-04-21 16:13:56,641 basehttp 124 "GET /mobiles/13818510759/count/ HTTP/1.1" 200 41
WARNING 2019-04-21 16:14:03,490 basehttp 124 "POST /register/ HTTP/1.1" 403 18
INFO 2019-04-21 16:14:04,870 basehttp 124 "GET /image_codes/09bc9521-cd85-4b87-b154-d106c056c4e0/ HTTP/1.1" 200 3106
INFO 2019-04-21 16:14:55,426 basehttp 124 "GET /register/ HTTP/1.1" 200 5287
INFO 2019-04-21 16:14:55,475 basehttp 124 "GET /image_codes/5acc86c3-7daf-4a23-9eb5-6e03e7ffec1e/ HTTP/1.1" 200 3030
INFO 2019-04-21 16:14:57,976 basehttp 124 "GET /usernames/admin/count/ HTTP/1.1" 200 41
INFO 2019-04-21 16:15:03,029 basehttp 124 "GET /mobiles/13818510759/count/ HTTP/1.1" 200 41
INFO 2019-04-21 16:15:08,153 basehttp 124 "GET /image_codes/ab4ceeaa-2eb7-4355-bdd7-0f1efe329861/ HTTP/1.1" 200 3100
INFO 2019-04-21 16:15:13,177 basehttp 124 "GET /sms_codes/13818510759/?image_code=mhyq&image_code_id=ab4ceeaa-2eb7-4355-bdd7-0f1efe329861 HTTP/1.1" 200 60
INFO 2019-04-21 16:15:13,179 basehttp 124 "GET /mobiles/13818510759/count/ HTTP/1.1" 200 41
INFO 2019-04-21 16:15:13,189 basehttp 124 "GET /image_codes/5d3a5615-4862-4cbe-b17a-b8c8939c61e5/ HTTP/1.1" 200 3159
INFO 2019-04-21 16:15:18,316 views 52 606207
INFO 2019-04-21 16:15:18,317 basehttp 124 "GET /sms_codes/13818510759/?image_code=kawf&image_code_id=5d3a5615-4862-4cbe-b17a-b8c8939c61e5 HTTP/1.1" 200 29
INFO 2019-04-21 16:15:18,319 basehttp 124 "GET /mobiles/13818510759/count/ HTTP/1.1" 200 41
WARNING 2019-04-21 16:15:27,888 basehttp 124 "POST /register/ HTTP/1.1" 403 18
INFO 2019-04-21 16:15:31,298 basehttp 124 "GET /image_codes/27fa7d1f-1dad-4799-9958-8828b5d916bc/ HTTP/1.1" 200 3777
INFO 2019-04-21 16:17:41,297 basehttp 124 "GET /register/ HTTP/1.1" 200 5287
INFO 2019-04-21 16:17:41,356 basehttp 124 "GET /image_codes/c7d04d04-5a8c-4351-897a-f19031cc4548/ HTTP/1.1" 200 3372
INFO 2019-04-21 16:17:41,439 basehttp 124 "GET /register/ HTTP/1.1" 200 5287
INFO 2019-04-21 16:17:41,500 basehttp 124 "GET /image_codes/b89c05d7-905b-4912-a65b-234205654253/ HTTP/1.1" 200 3191
INFO 2019-04-21 16:17:41,610 basehttp 124 "GET /register/ HTTP/1.1" 200 5287
INFO 2019-04-21 16:17:41,659 basehttp 124 "GET /image_codes/d0c289ba-3156-45b8-9805-2e28b1574b34/ HTTP/1.1" 200 3378
INFO 2019-04-21 16:17:46,013 basehttp 124 "GET /register/ HTTP/1.1" 200 5287
INFO 2019-04-21 16:17:46,060 basehttp 124 "GET /image_codes/4e6f7609-bb60-4017-a049-eb819e1eb022/ HTTP/1.1" 200 3569
INFO 2019-04-21 16:17:51,802 basehttp 124 "GET /usernames/admin/count/ HTTP/1.1" 200 41
INFO 2019-04-21 16:17:56,620 basehttp 124 "GET /mobiles/13818510759/count/ HTTP/1.1" 200 41
INFO 2019-04-21 16:18:04,054 views 31 rzra
INFO 2019-04-21 16:18:04,055 views 32 4e6f7609-bb60-4017-a049-eb819e1eb022
INFO 2019-04-21 16:18:04,056 views 56 677559
INFO 2019-04-21 16:18:04,057 basehttp 124 "GET /sms_codes/13818510759/?image_code=rzra&image_code_id=4e6f7609-bb60-4017-a049-eb819e1eb022 HTTP/1.1" 200 29
INFO 2019-04-21 16:18:04,059 basehttp 124 "GET /mobiles/13818510759/count/ HTTP/1.1" 200 41
WARNING 2019-04-21 16:18:24,510 basehttp 124 "POST /register/ HTTP/1.1" 403 18
INFO 2019-04-21 16:18:27,866 basehttp 124 "GET /image_codes/25e7ea86-3aee-4d10-a3f7-3ce8c9d65316/ HTTP/1.1" 200 3407
INFO 2019-04-21 16:19:20,651 basehttp 124 "GET /register/ HTTP/1.1" 200 5287
INFO 2019-04-21 16:19:20,696 basehttp 124 "GET /image_codes/14a3c3c9-442e-4772-ad1e-3ec897365452/ HTTP/1.1" 200 3187
INFO 2019-04-21 16:19:20,797 basehttp 124 "GET /register/ HTTP/1.1" 200 5287
INFO 2019-04-21 16:19:20,841 basehttp 124 "GET /image_codes/64df3dce-00d0-4d66-aaa8-21100e7461a1/ HTTP/1.1" 200 3285
INFO 2019-04-21 16:19:20,928 basehttp 124 "GET /register/ HTTP/1.1" 200 5287
INFO 2019-04-21 16:19:20,973 basehttp 124 "GET /image_codes/8e509a2b-4ddd-4733-afa9-16ec92b78fb4/ HTTP/1.1" 200 3706
INFO 2019-04-21 16:19:22,491 basehttp 124 "GET /usernames/admin/count/ HTTP/1.1" 200 41
INFO 2019-04-21 16:19:25,989 basehttp 124 "GET /mobiles/13818510759/count/ HTTP/1.1" 200 41
INFO 2019-04-21 16:19:29,482 basehttp 124 "GET /image_codes/f095e1c6-794f-491e-90ff-f53bd6f3f733/ HTTP/1.1" 200 3143
INFO 2019-04-21 16:19:32,853 views 56 780135
INFO 2019-04-21 16:19:32,855 basehttp 124 "GET /sms_codes/13818510759/?image_code=kt9h&image_code_id=f095e1c6-794f-491e-90ff-f53bd6f3f733 HTTP/1.1" 200 29
INFO 2019-04-21 16:19:32,857 basehttp 124 "GET /mobiles/13818510759/count/ HTTP/1.1" 200 41
WARNING 2019-04-21 16:19:53,355 basehttp 124 "POST /register/ HTTP/1.1" 403 18
INFO 2019-04-21 16:22:07,677 basehttp 124 "GET /register/ HTTP/1.1" 200 5287
INFO 2019-04-21 16:22:07,720 basehttp 124 "GET /image_codes/bceccbc9-f912-43a6-bc99-d3da4cddf18a/ HTTP/1.1" 200 3190
INFO 2019-04-21 16:22:07,842 basehttp 124 "GET /register/ HTTP/1.1" 200 5287
INFO 2019-04-21 16:22:07,886 basehttp 124 "GET /image_codes/009922b8-ce3b-4c4d-bf2f-e8a151640b39/ HTTP/1.1" 200 3172
INFO 2019-04-21 16:22:12,174 basehttp 124 "GET /register/ HTTP/1.1" 200 5287
INFO 2019-04-21 16:22:12,227 basehttp 124 "GET /image_codes/0d897541-02b0-4a41-adc9-10464a4accef/ HTTP/1.1" 200 3259
INFO 2019-04-21 16:22:15,650 basehttp 124 "GET /usernames/admin/count/ HTTP/1.1" 200 41
INFO 2019-04-21 16:22:18,406 basehttp 124 "GET /mobiles/13818510759/count/ HTTP/1.1" 200 41
INFO 2019-04-21 16:22:20,986 views 54 457734
INFO 2019-04-21 16:22:20,987 basehttp 124 "GET /sms_codes/13818510759/?image_code=fcbg&image_code_id=0d897541-02b0-4a41-adc9-10464a4accef HTTP/1.1" 200 29
INFO 2019-04-21 16:22:20,989 basehttp 124 "GET /mobiles/13818510759/count/ HTTP/1.1" 200 41
INFO 2019-04-21 16:22:26,789 views 33 admin
INFO 2019-04-21 16:22:26,789 views 34 123123123
INFO 2019-04-21 16:22:26,789 views 35 123123123
INFO 2019-04-21 16:22:26,789 views 36 None
INFO 2019-04-21 16:22:26,790 views 37 on
WARNING 2019-04-21 16:22:26,790 basehttp 124 "POST /register/ HTTP/1.1" 403 18
INFO 2019-04-21 16:22:32,356 basehttp 124 "GET /image_codes/d0194558-5bac-41a9-a660-0621b411e5ee/ HTTP/1.1" 200 3088
INFO 2019-04-21 16:23:09,685 basehttp 124 "GET /register/ HTTP/1.1" 200 5287
INFO 2019-04-21 16:23:09,745 basehttp 124 "GET /image_codes/53db63d6-0c7f-43cc-b29c-d7d6fe1540c8/ HTTP/1.1" 200 3349
INFO 2019-04-21 16:23:16,173 basehttp 124 "GET /usernames/admin/count/ HTTP/1.1" 200 41
INFO 2019-04-21 16:23:26,378 basehttp 124 "GET /mobiles/13818510759/count/ HTTP/1.1" 200 41
INFO 2019-04-21 16:23:30,011 views 54 744760
INFO 2019-04-21 16:23:30,012 basehttp 124 "GET /sms_codes/13818510759/?image_code=gzpo&image_code_id=53db63d6-0c7f-43cc-b29c-d7d6fe1540c8 HTTP/1.1" 200 29
INFO 2019-04-21 16:23:30,015 basehttp 124 "GET /mobiles/13818510759/count/ HTTP/1.1" 200 41
INFO 2019-04-21 16:23:41,037 basehttp 124 "POST /register/ HTTP/1.1" 200 5393
INFO 2019-04-21 16:23:41,081 basehttp 124 "GET /image_codes/d224097c-2000-4b3f-afaf-44c2f171f5da/ HTTP/1.1" 200 3191
INFO 2019-04-21 16:24:31,899 basehttp 124 "GET /register/ HTTP/1.1" 200 5287
INFO 2019-04-21 16:24:31,948 basehttp 124 "GET /image_codes/92159b94-82c7-4919-8f8b-7d02b1b32052/ HTTP/1.1" 200 3008
INFO 2019-04-21 16:24:35,112 basehttp 124 "GET /usernames/admin/count/ HTTP/1.1" 200 41
INFO 2019-04-21 16:24:38,674 basehttp 124 "GET /mobiles/13818510759/count/ HTTP/1.1" 200 41
INFO 2019-04-21 16:24:45,734 views 54 066237
INFO 2019-04-21 16:24:45,735 basehttp 124 "GET /sms_codes/13818510759/?image_code=osmi&image_code_id=92159b94-82c7-4919-8f8b-7d02b1b32052 HTTP/1.1" 200 29
INFO 2019-04-21 16:24:45,737 basehttp 124 "GET /mobiles/13818510759/count/ HTTP/1.1" 200 41
ERROR 2019-04-21 16:24:51,337 views 57 'phone' is an invalid keyword argument for this function
INFO 2019-04-21 16:24:51,338 basehttp 124 "POST /register/ HTTP/1.1" 200 5393
INFO 2019-04-21 16:24:51,388 basehttp 124 "GET /image_codes/4a8a6e2b-8990-48f3-b28a-316742f71649/ HTTP/1.1" 200 3253
INFO 2019-04-21 16:25:20,646 basehttp 124 "GET /register/ HTTP/1.1" 200 5287
INFO 2019-04-21 16:25:20,691 basehttp 124 "GET /image_codes/1b513512-3ad2-4efb-8390-db0a1fa92c67/ HTTP/1.1" 200 3244
INFO 2019-04-21 16:25:29,049 basehttp 124 "GET /usernames/admin/count/ HTTP/1.1" 200 41
INFO 2019-04-21 16:25:33,081 basehttp 124 "GET /mobiles/13818510759/count/ HTTP/1.1" 200 41
INFO 2019-04-21 16:25:37,151 basehttp 124 "GET /sms_codes/13818510759/?image_code=yaxt&image_code_id=1b513512-3ad2-4efb-8390-db0a1fa92c67 HTTP/1.1" 200 66
INFO 2019-04-21 16:25:37,154 basehttp 124 "GET /mobiles/13818510759/count/ HTTP/1.1" 200 41
INFO 2019-04-21 16:25:37,163 basehttp 124 "GET /image_codes/2b6f6f40-c862-4c2c-9f79-8e99c6e4559d/ HTTP/1.1" 200 3341
INFO 2019-04-21 16:25:43,080 basehttp 124 "GET /image_codes/173abd87-e45e-49bc-ba34-27ce1d741a20/ HTTP/1.1" 200 3243
INFO 2019-04-21 16:25:52,461 basehttp 124 "GET /sms_codes/13818510759/?image_code=ltbw&image_code_id=173abd87-e45e-49bc-ba34-27ce1d741a20 HTTP/1.1" 200 60
INFO 2019-04-21 16:25:52,463 basehttp 124 "GET /mobiles/13818510759/count/ HTTP/1.1" 200 41
INFO 2019-04-21 16:25:52,473 basehttp 124 "GET /image_codes/8b765c97-43bb-4181-a90b-c753dfdd8001/ HTTP/1.1" 200 3428
INFO 2019-04-21 16:25:55,572 views 54 404595
INFO 2019-04-21 16:25:55,573 basehttp 124 "GET /sms_codes/13818510759/?image_code=agjr&image_code_id=8b765c97-43bb-4181-a90b-c753dfdd8001 HTTP/1.1" 200 29
INFO 2019-04-21 16:25:55,576 basehttp 124 "GET /mobiles/13818510759/count/ HTTP/1.1" 200 41
INFO 2019-04-21 16:26:01,119 basehttp 124 "POST /register/ HTTP/1.1" 302 0
INFO 2019-04-21 16:26:01,128 basehttp 124 "GET / HTTP/1.1" 200 25122
WARNING 2019-04-21 16:26:01,244 base 152 Not Found: /carts/simple/
WARNING 2019-04-21 16:26:01,244 basehttp 124 "GET /carts/simple/ HTTP/1.1" 404 3068
WARNING 2019-04-21 16:26:10,941 basehttp 124 "GET /static/js/axios.min.map HTTP/1.1" 404 1661
INFO 2019-04-21 16:26:31,520 basehttp 124 "GET / HTTP/1.1" 200 25122
WARNING 2019-04-21 16:26:31,606 base 152 Not Found: /carts/simple/
WARNING 2019-04-21 16:26:31,606 basehttp 124 "GET /carts/simple/ HTTP/1.1" 404 3068
INFO 2019-04-21 18:35:14,699 basehttp 124 "GET / HTTP/1.1" 200 25122
WARNING 2019-04-21 18:35:14,812 base 152 Not Found: /carts/simple/
WARNING 2019-04-21 18:35:14,812 basehttp 124 "GET /carts/simple/ HTTP/1.1" 404 3068
INFO 2019-04-21 18:35:29,314 basehttp 124 "GET /register/ HTTP/1.1" 200 5287
INFO 2019-04-21 18:35:29,610 basehttp 124 "GET /image_codes/0d461369-6817-48c6-a4f6-c4f122a29594/ HTTP/1.1" 200 3143
INFO 2019-04-21 18:35:31,986 basehttp 124 "GET /usernames/admin/count/ HTTP/1.1" 200 41
INFO 2019-04-21 18:35:34,782 basehttp 124 "GET /usernames/admin1/count/ HTTP/1.1" 200 41
INFO 2019-04-21 18:35:37,624 basehttp 124 "GET /mobiles/13818510759/count/ HTTP/1.1" 200 41
INFO 2019-04-21 18:35:44,249 basehttp 124 "GET /mobiles/13818510722/count/ HTTP/1.1" 200 41
INFO 2019-04-21 18:35:49,261 views 55 076682
INFO 2019-04-21 18:35:49,266 basehttp 124 "GET /mobiles/13818510722/count/ HTTP/1.1" 200 41
ERROR 2019-04-21 18:35:49,269 exception 135 Internal Server Error: /sms_codes/13818510722/
Traceback (most recent call last):
  File "/Users/c/Envs/mdd_mall/lib/python3.7/site-packages/celery/local.py", line 317, in _get_current_object
    return object.__getattribute__(self, '__thing')
AttributeError: 'PromiseProxy' object has no attribute '__thing'

During handling of the above exception, another exception occurred:

Traceback (most recent call last):
  File "/Users/c/Envs/mdd_mall/lib/python3.7/site-packages/kombu/utils/objects.py", line 42, in __get__
    return obj.__dict__[self.__name__]
KeyError: 'data'

During handling of the above exception, another exception occurred:

Traceback (most recent call last):
  File "/Users/c/Envs/mdd_mall/lib/python3.7/site-packages/celery/loaders/base.py", line 144, in _smart_import
    return imp(path)
  File "/Users/c/Envs/mdd_mall/lib/python3.7/site-packages/celery/loaders/base.py", line 98, in import_from_cwd
    package=package,
  File "/Users/c/Envs/mdd_mall/lib/python3.7/site-packages/celery/utils/imports.py", line 111, in import_from_cwd
    return imp(module, package=package)
  File "/Users/c/Envs/mdd_mall/lib/python3.7/site-packages/celery/loaders/base.py", line 92, in import_module
    return importlib.import_module(module, package=package)
  File "/Users/c/Envs/mdd_mall/lib/python3.7/importlib/__init__.py", line 127, in import_module
    return _bootstrap._gcd_import(name[level:], package, level)
  File "<frozen importlib._bootstrap>", line 1006, in _gcd_import
  File "<frozen importlib._bootstrap>", line 983, in _find_and_load
  File "<frozen importlib._bootstrap>", line 953, in _find_and_load_unlocked
  File "<frozen importlib._bootstrap>", line 219, in _call_with_frames_removed
  File "<frozen importlib._bootstrap>", line 1006, in _gcd_import
  File "<frozen importlib._bootstrap>", line 983, in _find_and_load
  File "<frozen importlib._bootstrap>", line 965, in _find_and_load_unlocked
ModuleNotFoundError: No module named 'celery_tasks'

During handling of the above exception, another exception occurred:

Traceback (most recent call last):
  File "/Users/c/Envs/mdd_mall/lib/python3.7/site-packages/django/core/handlers/exception.py", line 41, in inner
    response = get_response(request)
  File "/Users/c/Envs/mdd_mall/lib/python3.7/site-packages/django/core/handlers/base.py", line 187, in _get_response
    response = self.process_exception_by_middleware(e, request)
  File "/Users/c/Envs/mdd_mall/lib/python3.7/site-packages/django/core/handlers/base.py", line 185, in _get_response
    response = wrapped_callback(request, *callback_args, **callback_kwargs)
  File "/Users/c/Envs/mdd_mall/lib/python3.7/site-packages/django/views/generic/base.py", line 68, in view
    return self.dispatch(request, *args, **kwargs)
  File "/Users/c/Envs/mdd_mall/lib/python3.7/site-packages/django/views/generic/base.py", line 88, in dispatch
    return handler(request, *args, **kwargs)
  File "/Users/c/Documents/mddproject/mddproject/mdd_mall/mdd_mall/apps/verifications/views.py", line 61, in get
    send_sms_code.delay(mobile,rand_int)
  File "/Users/c/Envs/mdd_mall/lib/python3.7/site-packages/celery/local.py", line 146, in __getattr__
    return getattr(self._get_current_object(), name)
  File "/Users/c/Envs/mdd_mall/lib/python3.7/site-packages/celery/local.py", line 319, in _get_current_object
    return self.__evaluate__()
  File "/Users/c/Envs/mdd_mall/lib/python3.7/site-packages/celery/local.py", line 349, in __evaluate__
    thing = Proxy._get_current_object(self)
  File "/Users/c/Envs/mdd_mall/lib/python3.7/site-packages/celery/local.py", line 109, in _get_current_object
    return loc(*self.__args, **self.__kwargs)
  File "/Users/c/Envs/mdd_mall/lib/python3.7/site-packages/celery/app/base.py", line 459, in _task_from_fun
    task.bind(self)  # connects task to this app
  File "/Users/c/Envs/mdd_mall/lib/python3.7/site-packages/celery/app/task.py", line 338, in bind
    setattr(cls, attr_name, conf[config_name])
  File "/Users/c/Envs/mdd_mall/lib/python3.7/site-packages/celery/utils/collections.py", line 437, in __getitem__
    return getitem(k)
  File "/Users/c/Envs/mdd_mall/lib/python3.7/site-packages/celery/utils/collections.py", line 286, in __getitem__
    return mapping[_key]
  File "/Users/c/Envs/mdd_mall/lib/python3.7/collections/__init__.py", line 1021, in __getitem__
    if key in self.data:
  File "/Users/c/Envs/mdd_mall/lib/python3.7/site-packages/kombu/utils/objects.py", line 44, in __get__
    value = obj.__dict__[self.__name__] = self.__get(obj)
  File "/Users/c/Envs/mdd_mall/lib/python3.7/site-packages/celery/app/base.py", line 141, in data
    return self.callback()
  File "/Users/c/Envs/mdd_mall/lib/python3.7/site-packages/celery/app/base.py", line 935, in _finalize_pending_conf
    conf = self._conf = self._load_config()
  File "/Users/c/Envs/mdd_mall/lib/python3.7/site-packages/celery/app/base.py", line 945, in _load_config
    self.loader.config_from_object(self._config_source)
  File "/Users/c/Envs/mdd_mall/lib/python3.7/site-packages/celery/loaders/base.py", line 126, in config_from_object
    obj = self._smart_import(obj, imp=self.import_from_cwd)
  File "/Users/c/Envs/mdd_mall/lib/python3.7/site-packages/celery/loaders/base.py", line 147, in _smart_import
    return symbol_by_name(path, imp=imp)
  File "/Users/c/Envs/mdd_mall/lib/python3.7/site-packages/kombu/utils/imports.py", line 56, in symbol_by_name
    module = imp(module_name, package=package, **kwargs)
  File "/Users/c/Envs/mdd_mall/lib/python3.7/site-packages/celery/loaders/base.py", line 98, in import_from_cwd
    package=package,
  File "/Users/c/Envs/mdd_mall/lib/python3.7/site-packages/celery/utils/imports.py", line 111, in import_from_cwd
    return imp(module, package=package)
  File "/Users/c/Envs/mdd_mall/lib/python3.7/site-packages/celery/loaders/base.py", line 92, in import_module
    return importlib.import_module(module, package=package)
  File "/Users/c/Envs/mdd_mall/lib/python3.7/importlib/__init__.py", line 127, in import_module
    return _bootstrap._gcd_import(name[level:], package, level)
  File "<frozen importlib._bootstrap>", line 1006, in _gcd_import
  File "<frozen importlib._bootstrap>", line 983, in _find_and_load
  File "<frozen importlib._bootstrap>", line 965, in _find_and_load_unlocked
ModuleNotFoundError: No module named 'celery_tasks'
ERROR 2019-04-21 18:35:49,331 basehttp 124 "GET /sms_codes/13818510722/?image_code=gtpb&image_code_id=0d461369-6817-48c6-a4f6-c4f122a29594 HTTP/1.1" 500 183828
INFO 2019-04-21 18:41:19,521 basehttp 124 "GET /register/ HTTP/1.1" 200 5287
INFO 2019-04-21 18:41:19,579 basehttp 124 "GET /image_codes/8b02bf3e-2353-4a00-955b-6c0631b27e69/ HTTP/1.1" 200 3079
INFO 2019-04-21 18:41:22,196 basehttp 124 "GET /usernames/admin1/count/ HTTP/1.1" 200 41
INFO 2019-04-21 18:41:29,026 basehttp 124 "GET /mobiles/13818510752/count/ HTTP/1.1" 200 41
INFO 2019-04-21 18:41:32,255 basehttp 124 "GET /image_codes/af06613c-5649-4599-81db-40b72ae50da5/ HTTP/1.1" 200 3354
INFO 2019-04-21 18:41:34,914 basehttp 124 "GET /sms_codes/13818510752/?image_code=rdsz&image_code_id=af06613c-5649-4599-81db-40b72ae50da5 HTTP/1.1" 200 60
INFO 2019-04-21 18:41:34,917 basehttp 124 "GET /mobiles/13818510752/count/ HTTP/1.1" 200 41
INFO 2019-04-21 18:41:34,927 basehttp 124 "GET /image_codes/6183906a-877f-4565-a263-38dfeeee9c7b/ HTTP/1.1" 200 3454
INFO 2019-04-21 18:41:36,734 basehttp 124 "GET /image_codes/f4e50181-6e51-4375-a7bc-899a6b3cc729/ HTTP/1.1" 200 3365
INFO 2019-04-21 18:41:43,956 views 54 179947
INFO 2019-04-21 18:41:43,958 basehttp 124 "GET /mobiles/13818510752/count/ HTTP/1.1" 200 41
ERROR 2019-04-21 18:41:44,104 exception 135 Internal Server Error: /sms_codes/13818510752/
Traceback (most recent call last):
  File "/Users/c/Envs/mdd_mall/lib/python3.7/site-packages/celery/local.py", line 317, in _get_current_object
    return object.__getattribute__(self, '__thing')
AttributeError: 'PromiseProxy' object has no attribute '__thing'

During handling of the above exception, another exception occurred:

Traceback (most recent call last):
  File "/Users/c/Envs/mdd_mall/lib/python3.7/site-packages/kombu/utils/objects.py", line 42, in __get__
    return obj.__dict__[self.__name__]
KeyError: 'data'

During handling of the above exception, another exception occurred:

Traceback (most recent call last):
  File "/Users/c/Envs/mdd_mall/lib/python3.7/site-packages/celery/loaders/base.py", line 144, in _smart_import
    return imp(path)
  File "/Users/c/Envs/mdd_mall/lib/python3.7/site-packages/celery/loaders/base.py", line 98, in import_from_cwd
    package=package,
  File "/Users/c/Envs/mdd_mall/lib/python3.7/site-packages/celery/utils/imports.py", line 111, in import_from_cwd
    return imp(module, package=package)
  File "/Users/c/Envs/mdd_mall/lib/python3.7/site-packages/celery/loaders/base.py", line 92, in import_module
    return importlib.import_module(module, package=package)
  File "/Users/c/Envs/mdd_mall/lib/python3.7/importlib/__init__.py", line 127, in import_module
    return _bootstrap._gcd_import(name[level:], package, level)
  File "<frozen importlib._bootstrap>", line 1006, in _gcd_import
  File "<frozen importlib._bootstrap>", line 983, in _find_and_load
  File "<frozen importlib._bootstrap>", line 953, in _find_and_load_unlocked
  File "<frozen importlib._bootstrap>", line 219, in _call_with_frames_removed
  File "<frozen importlib._bootstrap>", line 1006, in _gcd_import
  File "<frozen importlib._bootstrap>", line 983, in _find_and_load
  File "<frozen importlib._bootstrap>", line 965, in _find_and_load_unlocked
ModuleNotFoundError: No module named 'celery_tasks'

During handling of the above exception, another exception occurred:

Traceback (most recent call last):
  File "/Users/c/Envs/mdd_mall/lib/python3.7/site-packages/django/core/handlers/exception.py", line 41, in inner
    response = get_response(request)
  File "/Users/c/Envs/mdd_mall/lib/python3.7/site-packages/django/core/handlers/base.py", line 187, in _get_response
    response = self.process_exception_by_middleware(e, request)
  File "/Users/c/Envs/mdd_mall/lib/python3.7/site-packages/django/core/handlers/base.py", line 185, in _get_response
    response = wrapped_callback(request, *callback_args, **callback_kwargs)
  File "/Users/c/Envs/mdd_mall/lib/python3.7/site-packages/django/views/generic/base.py", line 68, in view
    return self.dispatch(request, *args, **kwargs)
  File "/Users/c/Envs/mdd_mall/lib/python3.7/site-packages/django/views/generic/base.py", line 88, in dispatch
    return handler(request, *args, **kwargs)
  File "/Users/c/Documents/mddproject/mddproject/mdd_mall/mdd_mall/apps/verifications/views.py", line 61, in get
    send_sms_code.delay(mobile,rand_int)
  File "/Users/c/Envs/mdd_mall/lib/python3.7/site-packages/celery/local.py", line 146, in __getattr__
    return getattr(self._get_current_object(), name)
  File "/Users/c/Envs/mdd_mall/lib/python3.7/site-packages/celery/local.py", line 319, in _get_current_object
    return self.__evaluate__()
  File "/Users/c/Envs/mdd_mall/lib/python3.7/site-packages/celery/local.py", line 349, in __evaluate__
    thing = Proxy._get_current_object(self)
  File "/Users/c/Envs/mdd_mall/lib/python3.7/site-packages/celery/local.py", line 109, in _get_current_object
    return loc(*self.__args, **self.__kwargs)
  File "/Users/c/Envs/mdd_mall/lib/python3.7/site-packages/celery/app/base.py", line 459, in _task_from_fun
    task.bind(self)  # connects task to this app
  File "/Users/c/Envs/mdd_mall/lib/python3.7/site-packages/celery/app/task.py", line 338, in bind
    setattr(cls, attr_name, conf[config_name])
  File "/Users/c/Envs/mdd_mall/lib/python3.7/site-packages/celery/utils/collections.py", line 437, in __getitem__
    return getitem(k)
  File "/Users/c/Envs/mdd_mall/lib/python3.7/site-packages/celery/utils/collections.py", line 286, in __getitem__
    return mapping[_key]
  File "/Users/c/Envs/mdd_mall/lib/python3.7/collections/__init__.py", line 1021, in __getitem__
    if key in self.data:
  File "/Users/c/Envs/mdd_mall/lib/python3.7/site-packages/kombu/utils/objects.py", line 44, in __get__
    value = obj.__dict__[self.__name__] = self.__get(obj)
  File "/Users/c/Envs/mdd_mall/lib/python3.7/site-packages/celery/app/base.py", line 141, in data
    return self.callback()
  File "/Users/c/Envs/mdd_mall/lib/python3.7/site-packages/celery/app/base.py", line 935, in _finalize_pending_conf
    conf = self._conf = self._load_config()
  File "/Users/c/Envs/mdd_mall/lib/python3.7/site-packages/celery/app/base.py", line 945, in _load_config
    self.loader.config_from_object(self._config_source)
  File "/Users/c/Envs/mdd_mall/lib/python3.7/site-packages/celery/loaders/base.py", line 126, in config_from_object
    obj = self._smart_import(obj, imp=self.import_from_cwd)
  File "/Users/c/Envs/mdd_mall/lib/python3.7/site-packages/celery/loaders/base.py", line 147, in _smart_import
    return symbol_by_name(path, imp=imp)
  File "/Users/c/Envs/mdd_mall/lib/python3.7/site-packages/kombu/utils/imports.py", line 56, in symbol_by_name
    module = imp(module_name, package=package, **kwargs)
  File "/Users/c/Envs/mdd_mall/lib/python3.7/site-packages/celery/loaders/base.py", line 98, in import_from_cwd
    package=package,
  File "/Users/c/Envs/mdd_mall/lib/python3.7/site-packages/celery/utils/imports.py", line 111, in import_from_cwd
    return imp(module, package=package)
  File "/Users/c/Envs/mdd_mall/lib/python3.7/site-packages/celery/loaders/base.py", line 92, in import_module
    return importlib.import_module(module, package=package)
  File "/Users/c/Envs/mdd_mall/lib/python3.7/importlib/__init__.py", line 127, in import_module
    return _bootstrap._gcd_import(name[level:], package, level)
  File "<frozen importlib._bootstrap>", line 1006, in _gcd_import
  File "<frozen importlib._bootstrap>", line 983, in _find_and_load
  File "<frozen importlib._bootstrap>", line 965, in _find_and_load_unlocked
ModuleNotFoundError: No module named 'celery_tasks'
ERROR 2019-04-21 18:41:44,172 basehttp 124 "GET /sms_codes/13818510752/?image_code=rcr6&image_code_id=f4e50181-6e51-4375-a7bc-899a6b3cc729 HTTP/1.1" 500 184043
INFO 2019-04-21 18:44:24,087 basehttp 124 "GET /register/ HTTP/1.1" 200 5287
INFO 2019-04-21 18:44:24,143 basehttp 124 "GET /image_codes/e735fdab-7b09-4274-baab-d9ca2357698a/ HTTP/1.1" 200 3327
INFO 2019-04-21 18:44:27,077 basehttp 124 "GET /usernames/admin1/count/ HTTP/1.1" 200 41
INFO 2019-04-21 18:44:34,686 basehttp 124 "GET /mobiles/13818510751/count/ HTTP/1.1" 200 41
INFO 2019-04-21 18:44:39,461 views 54 101774
ERROR 2019-04-21 18:44:39,462 exception 135 Internal Server Error: /sms_codes/13818510751/
Traceback (most recent call last):
  File "/Users/c/Envs/mdd_mall/lib/python3.7/site-packages/django/core/handlers/exception.py", line 41, in inner
    response = get_response(request)
  File "/Users/c/Envs/mdd_mall/lib/python3.7/site-packages/django/core/handlers/base.py", line 187, in _get_response
    response = self.process_exception_by_middleware(e, request)
  File "/Users/c/Envs/mdd_mall/lib/python3.7/site-packages/django/core/handlers/base.py", line 185, in _get_response
    response = wrapped_callback(request, *callback_args, **callback_kwargs)
  File "/Users/c/Envs/mdd_mall/lib/python3.7/site-packages/django/views/generic/base.py", line 68, in view
    return self.dispatch(request, *args, **kwargs)
  File "/Users/c/Envs/mdd_mall/lib/python3.7/site-packages/django/views/generic/base.py", line 88, in dispatch
    return handler(request, *args, **kwargs)
  File "/Users/c/Documents/mddproject/mddproject/mdd_mall/mdd_mall/apps/verifications/views.py", line 60, in get
    from mdd_mall.mdd_mall.celery_tasks.sms.tasks import send_sms_code
ModuleNotFoundError: No module named 'mdd_mall.mdd_mall'
INFO 2019-04-21 18:44:39,473 basehttp 124 "GET /mobiles/13818510751/count/ HTTP/1.1" 200 41
ERROR 2019-04-21 18:44:39,498 basehttp 124 "GET /sms_codes/13818510751/?image_code=6v3d&image_code_id=e735fdab-7b09-4274-baab-d9ca2357698a HTTP/1.1" 500 77459
INFO 2019-04-21 18:45:49,491 basehttp 124 "GET /register/ HTTP/1.1" 200 5287
INFO 2019-04-21 18:45:49,542 basehttp 124 "GET /image_codes/fb58e24f-aea3-4eee-99f3-f68cd67109ac/ HTTP/1.1" 200 3263
INFO 2019-04-21 18:45:52,845 basehttp 124 "GET /usernames/admin1/count/ HTTP/1.1" 200 41
INFO 2019-04-21 18:45:58,379 basehttp 124 "GET /mobiles/13818510722/count/ HTTP/1.1" 200 41
INFO 2019-04-21 18:46:01,968 views 54 663003
ERROR 2019-04-21 18:46:01,969 exception 135 Internal Server Error: /sms_codes/13818510722/
Traceback (most recent call last):
  File "/Users/c/Envs/mdd_mall/lib/python3.7/site-packages/django/core/handlers/exception.py", line 41, in inner
    response = get_response(request)
  File "/Users/c/Envs/mdd_mall/lib/python3.7/site-packages/django/core/handlers/base.py", line 187, in _get_response
    response = self.process_exception_by_middleware(e, request)
  File "/Users/c/Envs/mdd_mall/lib/python3.7/site-packages/django/core/handlers/base.py", line 185, in _get_response
    response = wrapped_callback(request, *callback_args, **callback_kwargs)
  File "/Users/c/Envs/mdd_mall/lib/python3.7/site-packages/django/views/generic/base.py", line 68, in view
    return self.dispatch(request, *args, **kwargs)
  File "/Users/c/Envs/mdd_mall/lib/python3.7/site-packages/django/views/generic/base.py", line 88, in dispatch
    return handler(request, *args, **kwargs)
  File "/Users/c/Documents/mddproject/mddproject/mdd_mall/mdd_mall/apps/verifications/views.py", line 60, in get
    from .mdd_mall.celery_tasks.sms.tasks import send_sms_code
ModuleNotFoundError: No module named 'verifications.mdd_mall'
INFO 2019-04-21 18:46:01,978 basehttp 124 "GET /mobiles/13818510722/count/ HTTP/1.1" 200 41
ERROR 2019-04-21 18:46:02,006 basehttp 124 "GET /sms_codes/13818510722/?image_code=f8ry&image_code_id=fb58e24f-aea3-4eee-99f3-f68cd67109ac HTTP/1.1" 500 77463
INFO 2019-04-21 19:19:13,467 basehttp 124 "GET / HTTP/1.1" 200 25122
WARNING 2019-04-21 19:19:13,806 base 152 Not Found: /carts/simple/
WARNING 2019-04-21 19:19:13,807 basehttp 124 "GET /carts/simple/ HTTP/1.1" 404 3068
WARNING 2019-04-21 19:19:13,841 base 152 Not Found: /favicon.ico
WARNING 2019-04-21 19:19:13,841 basehttp 124 "GET /favicon.ico HTTP/1.1" 404 3062
INFO 2019-04-21 19:19:20,426 basehttp 124 "GET /register/ HTTP/1.1" 200 5287
INFO 2019-04-21 19:19:20,552 basehttp 124 "GET /image_codes/b3f201db-88a5-4ede-9154-f0a32b3f7e66/ HTTP/1.1" 200 3159
INFO 2019-04-21 19:19:23,739 basehttp 124 "GET /usernames/admin1/count/ HTTP/1.1" 200 41
INFO 2019-04-21 19:19:35,661 basehttp 124 "GET /mobiles/13818510751/count/ HTTP/1.1" 200 41
INFO 2019-04-21 19:19:40,224 views 54 961667
INFO 2019-04-21 19:19:40,227 basehttp 124 "GET /mobiles/13818510751/count/ HTTP/1.1" 200 41
ERROR 2019-04-21 19:19:40,386 exception 135 Internal Server Error: /sms_codes/13818510751/
Traceback (most recent call last):
  File "/Users/c/Envs/mdd_mall/lib/python3.7/site-packages/celery/local.py", line 317, in _get_current_object
    return object.__getattribute__(self, '__thing')
AttributeError: 'PromiseProxy' object has no attribute '__thing'

During handling of the above exception, another exception occurred:

Traceback (most recent call last):
  File "/Users/c/Envs/mdd_mall/lib/python3.7/site-packages/kombu/utils/objects.py", line 42, in __get__
    return obj.__dict__[self.__name__]
KeyError: 'data'

During handling of the above exception, another exception occurred:

Traceback (most recent call last):
  File "/Users/c/Envs/mdd_mall/lib/python3.7/site-packages/celery/loaders/base.py", line 144, in _smart_import
    return imp(path)
  File "/Users/c/Envs/mdd_mall/lib/python3.7/site-packages/celery/loaders/base.py", line 98, in import_from_cwd
    package=package,
  File "/Users/c/Envs/mdd_mall/lib/python3.7/site-packages/celery/utils/imports.py", line 111, in import_from_cwd
    return imp(module, package=package)
  File "/Users/c/Envs/mdd_mall/lib/python3.7/site-packages/celery/loaders/base.py", line 92, in import_module
    return importlib.import_module(module, package=package)
  File "/Users/c/Envs/mdd_mall/lib/python3.7/importlib/__init__.py", line 127, in import_module
    return _bootstrap._gcd_import(name[level:], package, level)
  File "<frozen importlib._bootstrap>", line 1006, in _gcd_import
  File "<frozen importlib._bootstrap>", line 983, in _find_and_load
  File "<frozen importlib._bootstrap>", line 953, in _find_and_load_unlocked
  File "<frozen importlib._bootstrap>", line 219, in _call_with_frames_removed
  File "<frozen importlib._bootstrap>", line 1006, in _gcd_import
  File "<frozen importlib._bootstrap>", line 983, in _find_and_load
  File "<frozen importlib._bootstrap>", line 965, in _find_and_load_unlocked
ModuleNotFoundError: No module named 'celery_tasks'

During handling of the above exception, another exception occurred:

Traceback (most recent call last):
  File "/Users/c/Envs/mdd_mall/lib/python3.7/site-packages/django/core/handlers/exception.py", line 41, in inner
    response = get_response(request)
  File "/Users/c/Envs/mdd_mall/lib/python3.7/site-packages/django/core/handlers/base.py", line 187, in _get_response
    response = self.process_exception_by_middleware(e, request)
  File "/Users/c/Envs/mdd_mall/lib/python3.7/site-packages/django/core/handlers/base.py", line 185, in _get_response
    response = wrapped_callback(request, *callback_args, **callback_kwargs)
  File "/Users/c/Envs/mdd_mall/lib/python3.7/site-packages/django/views/generic/base.py", line 68, in view
    return self.dispatch(request, *args, **kwargs)
  File "/Users/c/Envs/mdd_mall/lib/python3.7/site-packages/django/views/generic/base.py", line 88, in dispatch
    return handler(request, *args, **kwargs)
  File "/Users/c/Documents/mddproject/mddproject/mdd_mall/mdd_mall/apps/verifications/views.py", line 61, in get
    send_sms_code.delay(mobile,rand_int)
  File "/Users/c/Envs/mdd_mall/lib/python3.7/site-packages/celery/local.py", line 146, in __getattr__
    return getattr(self._get_current_object(), name)
  File "/Users/c/Envs/mdd_mall/lib/python3.7/site-packages/celery/local.py", line 319, in _get_current_object
    return self.__evaluate__()
  File "/Users/c/Envs/mdd_mall/lib/python3.7/site-packages/celery/local.py", line 349, in __evaluate__
    thing = Proxy._get_current_object(self)
  File "/Users/c/Envs/mdd_mall/lib/python3.7/site-packages/celery/local.py", line 109, in _get_current_object
    return loc(*self.__args, **self.__kwargs)
  File "/Users/c/Envs/mdd_mall/lib/python3.7/site-packages/celery/app/base.py", line 459, in _task_from_fun
    task.bind(self)  # connects task to this app
  File "/Users/c/Envs/mdd_mall/lib/python3.7/site-packages/celery/app/task.py", line 338, in bind
    setattr(cls, attr_name, conf[config_name])
  File "/Users/c/Envs/mdd_mall/lib/python3.7/site-packages/celery/utils/collections.py", line 437, in __getitem__
    return getitem(k)
  File "/Users/c/Envs/mdd_mall/lib/python3.7/site-packages/celery/utils/collections.py", line 286, in __getitem__
    return mapping[_key]
  File "/Users/c/Envs/mdd_mall/lib/python3.7/collections/__init__.py", line 1021, in __getitem__
    if key in self.data:
  File "/Users/c/Envs/mdd_mall/lib/python3.7/site-packages/kombu/utils/objects.py", line 44, in __get__
    value = obj.__dict__[self.__name__] = self.__get(obj)
  File "/Users/c/Envs/mdd_mall/lib/python3.7/site-packages/celery/app/base.py", line 141, in data
    return self.callback()
  File "/Users/c/Envs/mdd_mall/lib/python3.7/site-packages/celery/app/base.py", line 935, in _finalize_pending_conf
    conf = self._conf = self._load_config()
  File "/Users/c/Envs/mdd_mall/lib/python3.7/site-packages/celery/app/base.py", line 945, in _load_config
    self.loader.config_from_object(self._config_source)
  File "/Users/c/Envs/mdd_mall/lib/python3.7/site-packages/celery/loaders/base.py", line 126, in config_from_object
    obj = self._smart_import(obj, imp=self.import_from_cwd)
  File "/Users/c/Envs/mdd_mall/lib/python3.7/site-packages/celery/loaders/base.py", line 147, in _smart_import
    return symbol_by_name(path, imp=imp)
  File "/Users/c/Envs/mdd_mall/lib/python3.7/site-packages/kombu/utils/imports.py", line 56, in symbol_by_name
    module = imp(module_name, package=package, **kwargs)
  File "/Users/c/Envs/mdd_mall/lib/python3.7/site-packages/celery/loaders/base.py", line 98, in import_from_cwd
    package=package,
  File "/Users/c/Envs/mdd_mall/lib/python3.7/site-packages/celery/utils/imports.py", line 111, in import_from_cwd
    return imp(module, package=package)
  File "/Users/c/Envs/mdd_mall/lib/python3.7/site-packages/celery/loaders/base.py", line 92, in import_module
    return importlib.import_module(module, package=package)
  File "/Users/c/Envs/mdd_mall/lib/python3.7/importlib/__init__.py", line 127, in import_module
    return _bootstrap._gcd_import(name[level:], package, level)
  File "<frozen importlib._bootstrap>", line 1006, in _gcd_import
  File "<frozen importlib._bootstrap>", line 983, in _find_and_load
  File "<frozen importlib._bootstrap>", line 965, in _find_and_load_unlocked
ModuleNotFoundError: No module named 'celery_tasks'
ERROR 2019-04-21 19:19:40,460 basehttp 124 "GET /sms_codes/13818510751/?image_code=afey&image_code_id=b3f201db-88a5-4ede-9154-f0a32b3f7e66 HTTP/1.1" 500 184043
INFO 2019-04-21 19:22:08,737 basehttp 124 "GET /register/ HTTP/1.1" 200 5287
INFO 2019-04-21 19:22:08,792 basehttp 124 "GET /image_codes/f81c4c42-ca93-4cc5-96f5-f405ab2edbe4/ HTTP/1.1" 200 3212
INFO 2019-04-21 19:22:12,975 basehttp 124 "GET /usernames/adminq/count/ HTTP/1.1" 200 41
INFO 2019-04-21 19:22:20,019 basehttp 124 "GET /mobiles/13818510751/count/ HTTP/1.1" 200 41
INFO 2019-04-21 19:22:22,927 basehttp 124 "GET /mobiles/13818510751/count/ HTTP/1.1" 200 41
INFO 2019-04-21 19:22:26,840 views 54 043235
INFO 2019-04-21 19:22:26,844 basehttp 124 "GET /mobiles/13818510751/count/ HTTP/1.1" 200 41
ERROR 2019-04-21 19:22:26,949 exception 135 Internal Server Error: /sms_codes/13818510751/
Traceback (most recent call last):
  File "/Users/c/Envs/mdd_mall/lib/python3.7/site-packages/celery/local.py", line 317, in _get_current_object
    return object.__getattribute__(self, '__thing')
AttributeError: 'PromiseProxy' object has no attribute '__thing'

During handling of the above exception, another exception occurred:

Traceback (most recent call last):
  File "/Users/c/Envs/mdd_mall/lib/python3.7/site-packages/kombu/utils/objects.py", line 42, in __get__
    return obj.__dict__[self.__name__]
KeyError: 'data'

During handling of the above exception, another exception occurred:

Traceback (most recent call last):
  File "/Users/c/Envs/mdd_mall/lib/python3.7/site-packages/celery/loaders/base.py", line 144, in _smart_import
    return imp(path)
  File "/Users/c/Envs/mdd_mall/lib/python3.7/site-packages/celery/loaders/base.py", line 98, in import_from_cwd
    package=package,
  File "/Users/c/Envs/mdd_mall/lib/python3.7/site-packages/celery/utils/imports.py", line 111, in import_from_cwd
    return imp(module, package=package)
  File "/Users/c/Envs/mdd_mall/lib/python3.7/site-packages/celery/loaders/base.py", line 92, in import_module
    return importlib.import_module(module, package=package)
  File "/Users/c/Envs/mdd_mall/lib/python3.7/importlib/__init__.py", line 127, in import_module
    return _bootstrap._gcd_import(name[level:], package, level)
  File "<frozen importlib._bootstrap>", line 1006, in _gcd_import
  File "<frozen importlib._bootstrap>", line 983, in _find_and_load
  File "<frozen importlib._bootstrap>", line 953, in _find_and_load_unlocked
  File "<frozen importlib._bootstrap>", line 219, in _call_with_frames_removed
  File "<frozen importlib._bootstrap>", line 1006, in _gcd_import
  File "<frozen importlib._bootstrap>", line 983, in _find_and_load
  File "<frozen importlib._bootstrap>", line 965, in _find_and_load_unlocked
ModuleNotFoundError: No module named 'celery_tasks'

During handling of the above exception, another exception occurred:

Traceback (most recent call last):
  File "/Users/c/Envs/mdd_mall/lib/python3.7/site-packages/django/core/handlers/exception.py", line 41, in inner
    response = get_response(request)
  File "/Users/c/Envs/mdd_mall/lib/python3.7/site-packages/django/core/handlers/base.py", line 187, in _get_response
    response = self.process_exception_by_middleware(e, request)
  File "/Users/c/Envs/mdd_mall/lib/python3.7/site-packages/django/core/handlers/base.py", line 185, in _get_response
    response = wrapped_callback(request, *callback_args, **callback_kwargs)
  File "/Users/c/Envs/mdd_mall/lib/python3.7/site-packages/django/views/generic/base.py", line 68, in view
    return self.dispatch(request, *args, **kwargs)
  File "/Users/c/Envs/mdd_mall/lib/python3.7/site-packages/django/views/generic/base.py", line 88, in dispatch
    return handler(request, *args, **kwargs)
  File "/Users/c/Documents/mddproject/mddproject/mdd_mall/mdd_mall/apps/verifications/views.py", line 61, in get
    send_sms_code.delay(mobile,rand_int)
  File "/Users/c/Envs/mdd_mall/lib/python3.7/site-packages/celery/local.py", line 146, in __getattr__
    return getattr(self._get_current_object(), name)
  File "/Users/c/Envs/mdd_mall/lib/python3.7/site-packages/celery/local.py", line 319, in _get_current_object
    return self.__evaluate__()
  File "/Users/c/Envs/mdd_mall/lib/python3.7/site-packages/celery/local.py", line 349, in __evaluate__
    thing = Proxy._get_current_object(self)
  File "/Users/c/Envs/mdd_mall/lib/python3.7/site-packages/celery/local.py", line 109, in _get_current_object
    return loc(*self.__args, **self.__kwargs)
  File "/Users/c/Envs/mdd_mall/lib/python3.7/site-packages/celery/app/base.py", line 459, in _task_from_fun
    task.bind(self)  # connects task to this app
  File "/Users/c/Envs/mdd_mall/lib/python3.7/site-packages/celery/app/task.py", line 338, in bind
    setattr(cls, attr_name, conf[config_name])
  File "/Users/c/Envs/mdd_mall/lib/python3.7/site-packages/celery/utils/collections.py", line 437, in __getitem__
    return getitem(k)
  File "/Users/c/Envs/mdd_mall/lib/python3.7/site-packages/celery/utils/collections.py", line 286, in __getitem__
    return mapping[_key]
  File "/Users/c/Envs/mdd_mall/lib/python3.7/collections/__init__.py", line 1021, in __getitem__
    if key in self.data:
  File "/Users/c/Envs/mdd_mall/lib/python3.7/site-packages/kombu/utils/objects.py", line 44, in __get__
    value = obj.__dict__[self.__name__] = self.__get(obj)
  File "/Users/c/Envs/mdd_mall/lib/python3.7/site-packages/celery/app/base.py", line 141, in data
    return self.callback()
  File "/Users/c/Envs/mdd_mall/lib/python3.7/site-packages/celery/app/base.py", line 935, in _finalize_pending_conf
    conf = self._conf = self._load_config()
  File "/Users/c/Envs/mdd_mall/lib/python3.7/site-packages/celery/app/base.py", line 945, in _load_config
    self.loader.config_from_object(self._config_source)
  File "/Users/c/Envs/mdd_mall/lib/python3.7/site-packages/celery/loaders/base.py", line 126, in config_from_object
    obj = self._smart_import(obj, imp=self.import_from_cwd)
  File "/Users/c/Envs/mdd_mall/lib/python3.7/site-packages/celery/loaders/base.py", line 147, in _smart_import
    return symbol_by_name(path, imp=imp)
  File "/Users/c/Envs/mdd_mall/lib/python3.7/site-packages/kombu/utils/imports.py", line 56, in symbol_by_name
    module = imp(module_name, package=package, **kwargs)
  File "/Users/c/Envs/mdd_mall/lib/python3.7/site-packages/celery/loaders/base.py", line 98, in import_from_cwd
    package=package,
  File "/Users/c/Envs/mdd_mall/lib/python3.7/site-packages/celery/utils/imports.py", line 111, in import_from_cwd
    return imp(module, package=package)
  File "/Users/c/Envs/mdd_mall/lib/python3.7/site-packages/celery/loaders/base.py", line 92, in import_module
    return importlib.import_module(module, package=package)
  File "/Users/c/Envs/mdd_mall/lib/python3.7/importlib/__init__.py", line 127, in import_module
    return _bootstrap._gcd_import(name[level:], package, level)
  File "<frozen importlib._bootstrap>", line 1006, in _gcd_import
  File "<frozen importlib._bootstrap>", line 983, in _find_and_load
  File "<frozen importlib._bootstrap>", line 965, in _find_and_load_unlocked
ModuleNotFoundError: No module named 'celery_tasks'
ERROR 2019-04-21 19:22:27,008 basehttp 124 "GET /sms_codes/13818510751/?image_code=l9du&image_code_id=f81c4c42-ca93-4cc5-96f5-f405ab2edbe4 HTTP/1.1" 500 184043
INFO 2019-04-21 19:45:48,372 basehttp 124 "GET /register/ HTTP/1.1" 200 5287
INFO 2019-04-21 19:45:48,434 basehttp 124 "GET /image_codes/c7f73430-7794-4323-b914-dd60a4783e65/ HTTP/1.1" 200 2722
INFO 2019-04-21 19:45:49,042 basehttp 124 "GET /register/ HTTP/1.1" 200 5287
INFO 2019-04-21 19:45:49,092 basehttp 124 "GET /image_codes/1fa2050e-6999-4841-88e9-55fcc2135432/ HTTP/1.1" 200 3468
INFO 2019-04-21 19:45:50,544 basehttp 124 "GET /usernames/admin1/count/ HTTP/1.1" 200 41
INFO 2019-04-21 19:45:55,599 basehttp 124 "GET /mobiles/13818510751/count/ HTTP/1.1" 200 41
INFO 2019-04-21 19:45:58,277 views 54 680587
INFO 2019-04-21 19:45:58,280 basehttp 124 "GET /mobiles/13818510751/count/ HTTP/1.1" 200 41
ERROR 2019-04-21 19:45:58,396 exception 135 Internal Server Error: /sms_codes/13818510751/
Traceback (most recent call last):
  File "/Users/c/Envs/mdd_mall/lib/python3.7/site-packages/celery/local.py", line 317, in _get_current_object
    return object.__getattribute__(self, '__thing')
AttributeError: 'PromiseProxy' object has no attribute '__thing'

During handling of the above exception, another exception occurred:

Traceback (most recent call last):
  File "/Users/c/Envs/mdd_mall/lib/python3.7/site-packages/kombu/utils/objects.py", line 42, in __get__
    return obj.__dict__[self.__name__]
KeyError: 'data'

During handling of the above exception, another exception occurred:

Traceback (most recent call last):
  File "/Users/c/Envs/mdd_mall/lib/python3.7/site-packages/celery/loaders/base.py", line 144, in _smart_import
    return imp(path)
  File "/Users/c/Envs/mdd_mall/lib/python3.7/site-packages/celery/loaders/base.py", line 98, in import_from_cwd
    package=package,
  File "/Users/c/Envs/mdd_mall/lib/python3.7/site-packages/celery/utils/imports.py", line 111, in import_from_cwd
    return imp(module, package=package)
  File "/Users/c/Envs/mdd_mall/lib/python3.7/site-packages/celery/loaders/base.py", line 92, in import_module
    return importlib.import_module(module, package=package)
  File "/Users/c/Envs/mdd_mall/lib/python3.7/importlib/__init__.py", line 127, in import_module
    return _bootstrap._gcd_import(name[level:], package, level)
  File "<frozen importlib._bootstrap>", line 1006, in _gcd_import
  File "<frozen importlib._bootstrap>", line 983, in _find_and_load
  File "<frozen importlib._bootstrap>", line 953, in _find_and_load_unlocked
  File "<frozen importlib._bootstrap>", line 219, in _call_with_frames_removed
  File "<frozen importlib._bootstrap>", line 1006, in _gcd_import
  File "<frozen importlib._bootstrap>", line 983, in _find_and_load
  File "<frozen importlib._bootstrap>", line 965, in _find_and_load_unlocked
ModuleNotFoundError: No module named 'celery_tasks'

During handling of the above exception, another exception occurred:

Traceback (most recent call last):
  File "/Users/c/Envs/mdd_mall/lib/python3.7/site-packages/django/core/handlers/exception.py", line 41, in inner
    response = get_response(request)
  File "/Users/c/Envs/mdd_mall/lib/python3.7/site-packages/django/core/handlers/base.py", line 187, in _get_response
    response = self.process_exception_by_middleware(e, request)
  File "/Users/c/Envs/mdd_mall/lib/python3.7/site-packages/django/core/handlers/base.py", line 185, in _get_response
    response = wrapped_callback(request, *callback_args, **callback_kwargs)
  File "/Users/c/Envs/mdd_mall/lib/python3.7/site-packages/django/views/generic/base.py", line 68, in view
    return self.dispatch(request, *args, **kwargs)
  File "/Users/c/Envs/mdd_mall/lib/python3.7/site-packages/django/views/generic/base.py", line 88, in dispatch
    return handler(request, *args, **kwargs)
  File "/Users/c/Documents/mddproject/mddproject/mdd_mall/mdd_mall/apps/verifications/views.py", line 61, in get
    send_sms_code.delay(mobile,rand_int)
  File "/Users/c/Envs/mdd_mall/lib/python3.7/site-packages/celery/local.py", line 146, in __getattr__
    return getattr(self._get_current_object(), name)
  File "/Users/c/Envs/mdd_mall/lib/python3.7/site-packages/celery/local.py", line 319, in _get_current_object
    return self.__evaluate__()
  File "/Users/c/Envs/mdd_mall/lib/python3.7/site-packages/celery/local.py", line 349, in __evaluate__
    thing = Proxy._get_current_object(self)
  File "/Users/c/Envs/mdd_mall/lib/python3.7/site-packages/celery/local.py", line 109, in _get_current_object
    return loc(*self.__args, **self.__kwargs)
  File "/Users/c/Envs/mdd_mall/lib/python3.7/site-packages/celery/app/base.py", line 459, in _task_from_fun
    task.bind(self)  # connects task to this app
  File "/Users/c/Envs/mdd_mall/lib/python3.7/site-packages/celery/app/task.py", line 338, in bind
    setattr(cls, attr_name, conf[config_name])
  File "/Users/c/Envs/mdd_mall/lib/python3.7/site-packages/celery/utils/collections.py", line 437, in __getitem__
    return getitem(k)
  File "/Users/c/Envs/mdd_mall/lib/python3.7/site-packages/celery/utils/collections.py", line 286, in __getitem__
    return mapping[_key]
  File "/Users/c/Envs/mdd_mall/lib/python3.7/collections/__init__.py", line 1021, in __getitem__
    if key in self.data:
  File "/Users/c/Envs/mdd_mall/lib/python3.7/site-packages/kombu/utils/objects.py", line 44, in __get__
    value = obj.__dict__[self.__name__] = self.__get(obj)
  File "/Users/c/Envs/mdd_mall/lib/python3.7/site-packages/celery/app/base.py", line 141, in data
    return self.callback()
  File "/Users/c/Envs/mdd_mall/lib/python3.7/site-packages/celery/app/base.py", line 935, in _finalize_pending_conf
    conf = self._conf = self._load_config()
  File "/Users/c/Envs/mdd_mall/lib/python3.7/site-packages/celery/app/base.py", line 945, in _load_config
    self.loader.config_from_object(self._config_source)
  File "/Users/c/Envs/mdd_mall/lib/python3.7/site-packages/celery/loaders/base.py", line 126, in config_from_object
    obj = self._smart_import(obj, imp=self.import_from_cwd)
  File "/Users/c/Envs/mdd_mall/lib/python3.7/site-packages/celery/loaders/base.py", line 147, in _smart_import
    return symbol_by_name(path, imp=imp)
  File "/Users/c/Envs/mdd_mall/lib/python3.7/site-packages/kombu/utils/imports.py", line 56, in symbol_by_name
    module = imp(module_name, package=package, **kwargs)
  File "/Users/c/Envs/mdd_mall/lib/python3.7/site-packages/celery/loaders/base.py", line 98, in import_from_cwd
    package=package,
  File "/Users/c/Envs/mdd_mall/lib/python3.7/site-packages/celery/utils/imports.py", line 111, in import_from_cwd
    return imp(module, package=package)
  File "/Users/c/Envs/mdd_mall/lib/python3.7/site-packages/celery/loaders/base.py", line 92, in import_module
    return importlib.import_module(module, package=package)
  File "/Users/c/Envs/mdd_mall/lib/python3.7/importlib/__init__.py", line 127, in import_module
    return _bootstrap._gcd_import(name[level:], package, level)
  File "<frozen importlib._bootstrap>", line 1006, in _gcd_import
  File "<frozen importlib._bootstrap>", line 983, in _find_and_load
  File "<frozen importlib._bootstrap>", line 965, in _find_and_load_unlocked
ModuleNotFoundError: No module named 'celery_tasks'
ERROR 2019-04-21 19:45:58,456 basehttp 124 "GET /sms_codes/13818510751/?image_code=ngze&image_code_id=1fa2050e-6999-4841-88e9-55fcc2135432 HTTP/1.1" 500 184043
INFO 2019-04-21 19:50:55,136 basehttp 124 "GET /image_codes/5e054d26-f8cf-4a80-9dd5-e4d59bb8623d/ HTTP/1.1" 200 3247
INFO 2019-04-21 19:50:56,515 basehttp 124 "GET /image_codes/6acd6ea7-04ff-4323-a51c-e81ffa6994d1/ HTTP/1.1" 200 2774
INFO 2019-04-21 19:50:59,296 views 54 953981
INFO 2019-04-21 19:50:59,300 basehttp 124 "GET /mobiles/13818510751/count/ HTTP/1.1" 200 41
ERROR 2019-04-21 19:50:59,408 exception 135 Internal Server Error: /sms_codes/13818510751/
Traceback (most recent call last):
  File "/Users/c/Envs/mdd_mall/lib/python3.7/site-packages/celery/local.py", line 317, in _get_current_object
    return object.__getattribute__(self, '__thing')
AttributeError: 'PromiseProxy' object has no attribute '__thing'

During handling of the above exception, another exception occurred:

Traceback (most recent call last):
  File "/Users/c/Envs/mdd_mall/lib/python3.7/site-packages/kombu/utils/objects.py", line 42, in __get__
    return obj.__dict__[self.__name__]
KeyError: 'data'

During handling of the above exception, another exception occurred:

Traceback (most recent call last):
  File "/Users/c/Envs/mdd_mall/lib/python3.7/site-packages/celery/loaders/base.py", line 144, in _smart_import
    return imp(path)
  File "/Users/c/Envs/mdd_mall/lib/python3.7/site-packages/celery/loaders/base.py", line 98, in import_from_cwd
    package=package,
  File "/Users/c/Envs/mdd_mall/lib/python3.7/site-packages/celery/utils/imports.py", line 111, in import_from_cwd
    return imp(module, package=package)
  File "/Users/c/Envs/mdd_mall/lib/python3.7/site-packages/celery/loaders/base.py", line 92, in import_module
    return importlib.import_module(module, package=package)
  File "/Users/c/Envs/mdd_mall/lib/python3.7/importlib/__init__.py", line 127, in import_module
    return _bootstrap._gcd_import(name[level:], package, level)
  File "<frozen importlib._bootstrap>", line 1006, in _gcd_import
  File "<frozen importlib._bootstrap>", line 983, in _find_and_load
  File "<frozen importlib._bootstrap>", line 953, in _find_and_load_unlocked
  File "<frozen importlib._bootstrap>", line 219, in _call_with_frames_removed
  File "<frozen importlib._bootstrap>", line 1006, in _gcd_import
  File "<frozen importlib._bootstrap>", line 983, in _find_and_load
  File "<frozen importlib._bootstrap>", line 965, in _find_and_load_unlocked
ModuleNotFoundError: No module named 'celery_tasks'

During handling of the above exception, another exception occurred:

Traceback (most recent call last):
  File "/Users/c/Envs/mdd_mall/lib/python3.7/site-packages/django/core/handlers/exception.py", line 41, in inner
    response = get_response(request)
  File "/Users/c/Envs/mdd_mall/lib/python3.7/site-packages/django/core/handlers/base.py", line 187, in _get_response
    response = self.process_exception_by_middleware(e, request)
  File "/Users/c/Envs/mdd_mall/lib/python3.7/site-packages/django/core/handlers/base.py", line 185, in _get_response
    response = wrapped_callback(request, *callback_args, **callback_kwargs)
  File "/Users/c/Envs/mdd_mall/lib/python3.7/site-packages/django/views/generic/base.py", line 68, in view
    return self.dispatch(request, *args, **kwargs)
  File "/Users/c/Envs/mdd_mall/lib/python3.7/site-packages/django/views/generic/base.py", line 88, in dispatch
    return handler(request, *args, **kwargs)
  File "/Users/c/Documents/mddproject/mddproject/mdd_mall/mdd_mall/apps/verifications/views.py", line 61, in get
    send_sms_code.delay(mobile,rand_int)
  File "/Users/c/Envs/mdd_mall/lib/python3.7/site-packages/celery/local.py", line 146, in __getattr__
    return getattr(self._get_current_object(), name)
  File "/Users/c/Envs/mdd_mall/lib/python3.7/site-packages/celery/local.py", line 319, in _get_current_object
    return self.__evaluate__()
  File "/Users/c/Envs/mdd_mall/lib/python3.7/site-packages/celery/local.py", line 349, in __evaluate__
    thing = Proxy._get_current_object(self)
  File "/Users/c/Envs/mdd_mall/lib/python3.7/site-packages/celery/local.py", line 109, in _get_current_object
    return loc(*self.__args, **self.__kwargs)
  File "/Users/c/Envs/mdd_mall/lib/python3.7/site-packages/celery/app/base.py", line 459, in _task_from_fun
    task.bind(self)  # connects task to this app
  File "/Users/c/Envs/mdd_mall/lib/python3.7/site-packages/celery/app/task.py", line 338, in bind
    setattr(cls, attr_name, conf[config_name])
  File "/Users/c/Envs/mdd_mall/lib/python3.7/site-packages/celery/utils/collections.py", line 437, in __getitem__
    return getitem(k)
  File "/Users/c/Envs/mdd_mall/lib/python3.7/site-packages/celery/utils/collections.py", line 286, in __getitem__
    return mapping[_key]
  File "/Users/c/Envs/mdd_mall/lib/python3.7/collections/__init__.py", line 1021, in __getitem__
    if key in self.data:
  File "/Users/c/Envs/mdd_mall/lib/python3.7/site-packages/kombu/utils/objects.py", line 44, in __get__
    value = obj.__dict__[self.__name__] = self.__get(obj)
  File "/Users/c/Envs/mdd_mall/lib/python3.7/site-packages/celery/app/base.py", line 141, in data
    return self.callback()
  File "/Users/c/Envs/mdd_mall/lib/python3.7/site-packages/celery/app/base.py", line 935, in _finalize_pending_conf
    conf = self._conf = self._load_config()
  File "/Users/c/Envs/mdd_mall/lib/python3.7/site-packages/celery/app/base.py", line 945, in _load_config
    self.loader.config_from_object(self._config_source)
  File "/Users/c/Envs/mdd_mall/lib/python3.7/site-packages/celery/loaders/base.py", line 126, in config_from_object
    obj = self._smart_import(obj, imp=self.import_from_cwd)
  File "/Users/c/Envs/mdd_mall/lib/python3.7/site-packages/celery/loaders/base.py", line 147, in _smart_import
    return symbol_by_name(path, imp=imp)
  File "/Users/c/Envs/mdd_mall/lib/python3.7/site-packages/kombu/utils/imports.py", line 56, in symbol_by_name
    module = imp(module_name, package=package, **kwargs)
  File "/Users/c/Envs/mdd_mall/lib/python3.7/site-packages/celery/loaders/base.py", line 98, in import_from_cwd
    package=package,
  File "/Users/c/Envs/mdd_mall/lib/python3.7/site-packages/celery/utils/imports.py", line 111, in import_from_cwd
    return imp(module, package=package)
  File "/Users/c/Envs/mdd_mall/lib/python3.7/site-packages/celery/loaders/base.py", line 92, in import_module
    return importlib.import_module(module, package=package)
  File "/Users/c/Envs/mdd_mall/lib/python3.7/importlib/__init__.py", line 127, in import_module
    return _bootstrap._gcd_import(name[level:], package, level)
  File "<frozen importlib._bootstrap>", line 1006, in _gcd_import
  File "<frozen importlib._bootstrap>", line 983, in _find_and_load
  File "<frozen importlib._bootstrap>", line 965, in _find_and_load_unlocked
ModuleNotFoundError: No module named 'celery_tasks'
ERROR 2019-04-21 19:50:59,470 basehttp 124 "GET /sms_codes/13818510751/?image_code=trjf&image_code_id=6acd6ea7-04ff-4323-a51c-e81ffa6994d1 HTTP/1.1" 500 184043
INFO 2019-04-21 19:54:03,553 basehttp 124 "GET /register/ HTTP/1.1" 200 5287
INFO 2019-04-21 19:54:03,604 basehttp 124 "GET /image_codes/2bb104c5-379f-4856-be00-43cf77c4a10c/ HTTP/1.1" 200 3432
INFO 2019-04-21 19:54:03,714 basehttp 124 "GET /register/ HTTP/1.1" 200 5287
INFO 2019-04-21 19:54:03,763 basehttp 124 "GET /image_codes/bd6dcb2b-1e1e-49fc-9b21-edb56ea5d0b5/ HTTP/1.1" 200 3154
INFO 2019-04-21 19:54:03,881 basehttp 124 "GET /register/ HTTP/1.1" 200 5287
INFO 2019-04-21 19:54:03,930 basehttp 124 "GET /image_codes/af5ab100-a8b9-436d-98c5-83839a5c6ac5/ HTTP/1.1" 200 2926
INFO 2019-04-21 19:54:04,041 basehttp 124 "GET /register/ HTTP/1.1" 200 5287
INFO 2019-04-21 19:54:04,087 basehttp 124 "GET /image_codes/708f6e55-3c6b-4c37-8e08-ff7c53c04272/ HTTP/1.1" 200 3225
INFO 2019-04-21 19:54:04,202 basehttp 124 "GET /register/ HTTP/1.1" 200 5287
INFO 2019-04-21 19:54:04,250 basehttp 124 "GET /image_codes/e111807c-ba1a-40ff-9973-c045738aa624/ HTTP/1.1" 200 2975
INFO 2019-04-21 19:54:05,681 basehttp 124 "GET /usernames/admin1/count/ HTTP/1.1" 200 41
INFO 2019-04-21 19:54:12,017 basehttp 124 "GET /mobiles/13818510751/count/ HTTP/1.1" 200 41
INFO 2019-04-21 19:54:14,955 views 54 083982
ERROR 2019-04-21 19:54:14,956 exception 135 Internal Server Error: /sms_codes/13818510751/
Traceback (most recent call last):
  File "/Users/c/Envs/mdd_mall/lib/python3.7/site-packages/django/core/handlers/exception.py", line 41, in inner
    response = get_response(request)
  File "/Users/c/Envs/mdd_mall/lib/python3.7/site-packages/django/core/handlers/base.py", line 187, in _get_response
    response = self.process_exception_by_middleware(e, request)
  File "/Users/c/Envs/mdd_mall/lib/python3.7/site-packages/django/core/handlers/base.py", line 185, in _get_response
    response = wrapped_callback(request, *callback_args, **callback_kwargs)
  File "/Users/c/Envs/mdd_mall/lib/python3.7/site-packages/django/views/generic/base.py", line 68, in view
    return self.dispatch(request, *args, **kwargs)
  File "/Users/c/Envs/mdd_mall/lib/python3.7/site-packages/django/views/generic/base.py", line 88, in dispatch
    return handler(request, *args, **kwargs)
  File "/Users/c/Documents/mddproject/mddproject/mdd_mall/mdd_mall/apps/verifications/views.py", line 60, in get
    from celery_tasks.sms.tasks import send_sms_code
ModuleNotFoundError: No module named 'celery_tasks'
INFO 2019-04-21 19:54:14,966 basehttp 124 "GET /mobiles/13818510751/count/ HTTP/1.1" 200 41
ERROR 2019-04-21 19:54:14,991 basehttp 124 "GET /sms_codes/13818510751/?image_code=s9hg&image_code_id=e111807c-ba1a-40ff-9973-c045738aa624 HTTP/1.1" 500 77487
INFO 2019-04-21 19:54:41,366 basehttp 124 "GET /register/ HTTP/1.1" 200 5287
INFO 2019-04-21 19:54:41,425 basehttp 124 "GET /image_codes/c048d3ea-544e-4a1c-a935-881d9e1d55c8/ HTTP/1.1" 200 3108
INFO 2019-04-21 19:54:41,532 basehttp 124 "GET /register/ HTTP/1.1" 200 5287
INFO 2019-04-21 19:54:41,585 basehttp 124 "GET /image_codes/42523ab2-f008-43f8-aaa3-f2a6a89a1a33/ HTTP/1.1" 200 3277
INFO 2019-04-21 19:54:41,699 basehttp 124 "GET /register/ HTTP/1.1" 200 5287
INFO 2019-04-21 19:54:41,747 basehttp 124 "GET /image_codes/f03091b4-6874-4c1e-addd-e9c2c260d36a/ HTTP/1.1" 200 3465
INFO 2019-04-21 19:54:41,868 basehttp 124 "GET /register/ HTTP/1.1" 200 5287
INFO 2019-04-21 19:54:41,918 basehttp 124 "GET /image_codes/dbe9d469-44ef-44fa-b0af-c3702140bbe6/ HTTP/1.1" 200 3153
INFO 2019-04-21 19:54:42,031 basehttp 124 "GET /register/ HTTP/1.1" 200 5287
INFO 2019-04-21 19:54:42,079 basehttp 124 "GET /image_codes/f121e741-9954-4544-b85c-d054869e436d/ HTTP/1.1" 200 3424
INFO 2019-04-21 19:54:42,200 basehttp 124 "GET /register/ HTTP/1.1" 200 5287
INFO 2019-04-21 19:54:42,249 basehttp 124 "GET /image_codes/9fa19fb8-3bc7-46bb-b98a-cb0b4706a3ce/ HTTP/1.1" 200 2686
INFO 2019-04-21 19:54:43,685 basehttp 124 "GET /usernames/admin1/count/ HTTP/1.1" 200 41
INFO 2019-04-21 19:54:48,322 basehttp 124 "GET /mobiles/13818510751/count/ HTTP/1.1" 200 41
INFO 2019-04-21 19:54:51,060 basehttp 124 "GET /sms_codes/13818510751/?image_code=yg6c&image_code_id=9fa19fb8-3bc7-46bb-b98a-cb0b4706a3ce HTTP/1.1" 200 66
INFO 2019-04-21 19:54:51,063 basehttp 124 "GET /mobiles/13818510751/count/ HTTP/1.1" 200 41
INFO 2019-04-21 19:54:51,073 basehttp 124 "GET /image_codes/395dc8bc-a41f-45f0-906e-adcf428c0743/ HTTP/1.1" 200 2828
INFO 2019-04-21 19:54:56,374 basehttp 124 "GET /image_codes/deb00853-26da-4e1b-8c29-ef1b08f595f6/ HTTP/1.1" 200 3435
INFO 2019-04-21 19:55:00,956 basehttp 124 "GET /sms_codes/13818510751/?image_code=rmrv&image_code_id=deb00853-26da-4e1b-8c29-ef1b08f595f6 HTTP/1.1" 200 66
INFO 2019-04-21 19:55:00,959 basehttp 124 "GET /mobiles/13818510751/count/ HTTP/1.1" 200 41
INFO 2019-04-21 19:55:00,968 basehttp 124 "GET /image_codes/1044a9c7-39d5-4ea9-89d6-51eb2357be54/ HTTP/1.1" 200 3449
INFO 2019-04-21 19:55:06,239 basehttp 124 "GET /image_codes/789c3f1f-c9f6-4356-956f-b2da9ba95dea/ HTTP/1.1" 200 3183
INFO 2019-04-21 19:55:19,349 views 54 279417
INFO 2019-04-21 19:55:19,352 basehttp 124 "GET /mobiles/13818510751/count/ HTTP/1.1" 200 41
ERROR 2019-04-21 19:55:19,460 exception 135 Internal Server Error: /sms_codes/13818510751/
Traceback (most recent call last):
  File "/Users/c/Envs/mdd_mall/lib/python3.7/site-packages/celery/local.py", line 317, in _get_current_object
    return object.__getattribute__(self, '__thing')
AttributeError: 'PromiseProxy' object has no attribute '__thing'

During handling of the above exception, another exception occurred:

Traceback (most recent call last):
  File "/Users/c/Envs/mdd_mall/lib/python3.7/site-packages/kombu/utils/objects.py", line 42, in __get__
    return obj.__dict__[self.__name__]
KeyError: 'data'

During handling of the above exception, another exception occurred:

Traceback (most recent call last):
  File "/Users/c/Envs/mdd_mall/lib/python3.7/site-packages/celery/loaders/base.py", line 144, in _smart_import
    return imp(path)
  File "/Users/c/Envs/mdd_mall/lib/python3.7/site-packages/celery/loaders/base.py", line 98, in import_from_cwd
    package=package,
  File "/Users/c/Envs/mdd_mall/lib/python3.7/site-packages/celery/utils/imports.py", line 111, in import_from_cwd
    return imp(module, package=package)
  File "/Users/c/Envs/mdd_mall/lib/python3.7/site-packages/celery/loaders/base.py", line 92, in import_module
    return importlib.import_module(module, package=package)
  File "/Users/c/Envs/mdd_mall/lib/python3.7/importlib/__init__.py", line 127, in import_module
    return _bootstrap._gcd_import(name[level:], package, level)
  File "<frozen importlib._bootstrap>", line 1006, in _gcd_import
  File "<frozen importlib._bootstrap>", line 983, in _find_and_load
  File "<frozen importlib._bootstrap>", line 953, in _find_and_load_unlocked
  File "<frozen importlib._bootstrap>", line 219, in _call_with_frames_removed
  File "<frozen importlib._bootstrap>", line 1006, in _gcd_import
  File "<frozen importlib._bootstrap>", line 983, in _find_and_load
  File "<frozen importlib._bootstrap>", line 965, in _find_and_load_unlocked
ModuleNotFoundError: No module named 'celery_tasks'

During handling of the above exception, another exception occurred:

Traceback (most recent call last):
  File "/Users/c/Envs/mdd_mall/lib/python3.7/site-packages/django/core/handlers/exception.py", line 41, in inner
    response = get_response(request)
  File "/Users/c/Envs/mdd_mall/lib/python3.7/site-packages/django/core/handlers/base.py", line 187, in _get_response
    response = self.process_exception_by_middleware(e, request)
  File "/Users/c/Envs/mdd_mall/lib/python3.7/site-packages/django/core/handlers/base.py", line 185, in _get_response
    response = wrapped_callback(request, *callback_args, **callback_kwargs)
  File "/Users/c/Envs/mdd_mall/lib/python3.7/site-packages/django/views/generic/base.py", line 68, in view
    return self.dispatch(request, *args, **kwargs)
  File "/Users/c/Envs/mdd_mall/lib/python3.7/site-packages/django/views/generic/base.py", line 88, in dispatch
    return handler(request, *args, **kwargs)
  File "/Users/c/Documents/mddproject/mddproject/mdd_mall/mdd_mall/apps/verifications/views.py", line 61, in get
    send_sms_code.delay(mobile,rand_int)
  File "/Users/c/Envs/mdd_mall/lib/python3.7/site-packages/celery/local.py", line 146, in __getattr__
    return getattr(self._get_current_object(), name)
  File "/Users/c/Envs/mdd_mall/lib/python3.7/site-packages/celery/local.py", line 319, in _get_current_object
    return self.__evaluate__()
  File "/Users/c/Envs/mdd_mall/lib/python3.7/site-packages/celery/local.py", line 349, in __evaluate__
    thing = Proxy._get_current_object(self)
  File "/Users/c/Envs/mdd_mall/lib/python3.7/site-packages/celery/local.py", line 109, in _get_current_object
    return loc(*self.__args, **self.__kwargs)
  File "/Users/c/Envs/mdd_mall/lib/python3.7/site-packages/celery/app/base.py", line 459, in _task_from_fun
    task.bind(self)  # connects task to this app
  File "/Users/c/Envs/mdd_mall/lib/python3.7/site-packages/celery/app/task.py", line 338, in bind
    setattr(cls, attr_name, conf[config_name])
  File "/Users/c/Envs/mdd_mall/lib/python3.7/site-packages/celery/utils/collections.py", line 437, in __getitem__
    return getitem(k)
  File "/Users/c/Envs/mdd_mall/lib/python3.7/site-packages/celery/utils/collections.py", line 286, in __getitem__
    return mapping[_key]
  File "/Users/c/Envs/mdd_mall/lib/python3.7/collections/__init__.py", line 1021, in __getitem__
    if key in self.data:
  File "/Users/c/Envs/mdd_mall/lib/python3.7/site-packages/kombu/utils/objects.py", line 44, in __get__
    value = obj.__dict__[self.__name__] = self.__get(obj)
  File "/Users/c/Envs/mdd_mall/lib/python3.7/site-packages/celery/app/base.py", line 141, in data
    return self.callback()
  File "/Users/c/Envs/mdd_mall/lib/python3.7/site-packages/celery/app/base.py", line 935, in _finalize_pending_conf
    conf = self._conf = self._load_config()
  File "/Users/c/Envs/mdd_mall/lib/python3.7/site-packages/celery/app/base.py", line 945, in _load_config
    self.loader.config_from_object(self._config_source)
  File "/Users/c/Envs/mdd_mall/lib/python3.7/site-packages/celery/loaders/base.py", line 126, in config_from_object
    obj = self._smart_import(obj, imp=self.import_from_cwd)
  File "/Users/c/Envs/mdd_mall/lib/python3.7/site-packages/celery/loaders/base.py", line 147, in _smart_import
    return symbol_by_name(path, imp=imp)
  File "/Users/c/Envs/mdd_mall/lib/python3.7/site-packages/kombu/utils/imports.py", line 56, in symbol_by_name
    module = imp(module_name, package=package, **kwargs)
  File "/Users/c/Envs/mdd_mall/lib/python3.7/site-packages/celery/loaders/base.py", line 98, in import_from_cwd
    package=package,
  File "/Users/c/Envs/mdd_mall/lib/python3.7/site-packages/celery/utils/imports.py", line 111, in import_from_cwd
    return imp(module, package=package)
  File "/Users/c/Envs/mdd_mall/lib/python3.7/site-packages/celery/loaders/base.py", line 92, in import_module
    return importlib.import_module(module, package=package)
  File "/Users/c/Envs/mdd_mall/lib/python3.7/importlib/__init__.py", line 127, in import_module
    return _bootstrap._gcd_import(name[level:], package, level)
  File "<frozen importlib._bootstrap>", line 1006, in _gcd_import
  File "<frozen importlib._bootstrap>", line 983, in _find_and_load
  File "<frozen importlib._bootstrap>", line 965, in _find_and_load_unlocked
ModuleNotFoundError: No module named 'celery_tasks'
ERROR 2019-04-21 19:55:19,520 basehttp 124 "GET /sms_codes/13818510751/?image_code=4kcl&image_code_id=789c3f1f-c9f6-4356-956f-b2da9ba95dea HTTP/1.1" 500 184127
INFO 2019-04-21 19:56:02,156 basehttp 124 "GET /register/ HTTP/1.1" 200 5287
INFO 2019-04-21 19:56:02,212 basehttp 124 "GET /image_codes/c4309a25-6642-4b85-bdbc-0b1c144043ab/ HTTP/1.1" 200 3302
INFO 2019-04-21 19:56:02,306 basehttp 124 "GET /register/ HTTP/1.1" 200 5287
INFO 2019-04-21 19:56:02,351 basehttp 124 "GET /image_codes/6af8067d-c9d2-40fe-a006-939138bcb9c5/ HTTP/1.1" 200 3258
INFO 2019-04-21 19:56:02,437 basehttp 124 "GET /register/ HTTP/1.1" 200 5287
INFO 2019-04-21 19:56:02,483 basehttp 124 "GET /image_codes/10901b88-ff54-44c5-99ec-44866255b99f/ HTTP/1.1" 200 3577
INFO 2019-04-21 19:56:02,593 basehttp 124 "GET /register/ HTTP/1.1" 200 5287
INFO 2019-04-21 19:56:02,632 basehttp 124 "GET /image_codes/6dd603bf-7c21-46e8-bb46-a15376feef9c/ HTTP/1.1" 200 3484
INFO 2019-04-21 19:56:02,753 basehttp 124 "GET /register/ HTTP/1.1" 200 5287
INFO 2019-04-21 19:56:02,790 basehttp 124 "GET /image_codes/28ac757e-cd9a-43e9-9c62-77c62d1d043e/ HTTP/1.1" 200 3413
INFO 2019-04-21 19:56:02,921 basehttp 124 "GET /register/ HTTP/1.1" 200 5287
INFO 2019-04-21 19:56:02,969 basehttp 124 "GET /image_codes/56448664-475c-4195-9e95-31b008a987e6/ HTTP/1.1" 200 3583
INFO 2019-04-21 19:56:04,529 basehttp 124 "GET /usernames/admin1/count/ HTTP/1.1" 200 41
INFO 2019-04-21 19:56:09,658 basehttp 124 "GET /mobiles/13818510751/count/ HTTP/1.1" 200 41
INFO 2019-04-21 19:56:11,683 basehttp 124 "GET /sms_codes/13818510751/?image_code=pwyn&image_code_id=56448664-475c-4195-9e95-31b008a987e6 HTTP/1.1" 200 66
INFO 2019-04-21 19:56:11,686 basehttp 124 "GET /mobiles/13818510751/count/ HTTP/1.1" 200 41
INFO 2019-04-21 19:56:11,696 basehttp 124 "GET /image_codes/71fa8841-0a7c-4e85-9254-f769582f1603/ HTTP/1.1" 200 2869
INFO 2019-04-21 19:56:50,454 basehttp 124 "GET /image_codes/59168e2e-9ac8-4baa-befc-5ef4905239a7/ HTTP/1.1" 200 2854
INFO 2019-04-21 19:56:56,050 views 56 991122
INFO 2019-04-21 19:56:56,054 basehttp 124 "GET /mobiles/13818510751/count/ HTTP/1.1" 200 41
ERROR 2019-04-21 19:56:56,058 exception 135 Internal Server Error: /sms_codes/13818510751/
Traceback (most recent call last):
  File "/Users/c/Envs/mdd_mall/lib/python3.7/site-packages/celery/local.py", line 317, in _get_current_object
    return object.__getattribute__(self, '__thing')
AttributeError: 'PromiseProxy' object has no attribute '__thing'

During handling of the above exception, another exception occurred:

Traceback (most recent call last):
  File "/Users/c/Envs/mdd_mall/lib/python3.7/site-packages/kombu/utils/objects.py", line 42, in __get__
    return obj.__dict__[self.__name__]
KeyError: 'data'

During handling of the above exception, another exception occurred:

Traceback (most recent call last):
  File "/Users/c/Envs/mdd_mall/lib/python3.7/site-packages/celery/loaders/base.py", line 144, in _smart_import
    return imp(path)
  File "/Users/c/Envs/mdd_mall/lib/python3.7/site-packages/celery/loaders/base.py", line 98, in import_from_cwd
    package=package,
  File "/Users/c/Envs/mdd_mall/lib/python3.7/site-packages/celery/utils/imports.py", line 111, in import_from_cwd
    return imp(module, package=package)
  File "/Users/c/Envs/mdd_mall/lib/python3.7/site-packages/celery/loaders/base.py", line 92, in import_module
    return importlib.import_module(module, package=package)
  File "/Users/c/Envs/mdd_mall/lib/python3.7/importlib/__init__.py", line 127, in import_module
    return _bootstrap._gcd_import(name[level:], package, level)
  File "<frozen importlib._bootstrap>", line 1006, in _gcd_import
  File "<frozen importlib._bootstrap>", line 983, in _find_and_load
  File "<frozen importlib._bootstrap>", line 953, in _find_and_load_unlocked
  File "<frozen importlib._bootstrap>", line 219, in _call_with_frames_removed
  File "<frozen importlib._bootstrap>", line 1006, in _gcd_import
  File "<frozen importlib._bootstrap>", line 983, in _find_and_load
  File "<frozen importlib._bootstrap>", line 965, in _find_and_load_unlocked
ModuleNotFoundError: No module named 'celery_tasks'

During handling of the above exception, another exception occurred:

Traceback (most recent call last):
  File "/Users/c/Envs/mdd_mall/lib/python3.7/site-packages/django/core/handlers/exception.py", line 41, in inner
    response = get_response(request)
  File "/Users/c/Envs/mdd_mall/lib/python3.7/site-packages/django/core/handlers/base.py", line 187, in _get_response
    response = self.process_exception_by_middleware(e, request)
  File "/Users/c/Envs/mdd_mall/lib/python3.7/site-packages/django/core/handlers/base.py", line 185, in _get_response
    response = wrapped_callback(request, *callback_args, **callback_kwargs)
  File "/Users/c/Envs/mdd_mall/lib/python3.7/site-packages/django/views/generic/base.py", line 68, in view
    return self.dispatch(request, *args, **kwargs)
  File "/Users/c/Envs/mdd_mall/lib/python3.7/site-packages/django/views/generic/base.py", line 88, in dispatch
    return handler(request, *args, **kwargs)
  File "/Users/c/Documents/mddproject/mddproject/mdd_mall/mdd_mall/apps/verifications/views.py", line 62, in get
    send_sms_code.delay(mobile,rand_int)
  File "/Users/c/Envs/mdd_mall/lib/python3.7/site-packages/celery/local.py", line 146, in __getattr__
    return getattr(self._get_current_object(), name)
  File "/Users/c/Envs/mdd_mall/lib/python3.7/site-packages/celery/local.py", line 319, in _get_current_object
    return self.__evaluate__()
  File "/Users/c/Envs/mdd_mall/lib/python3.7/site-packages/celery/local.py", line 349, in __evaluate__
    thing = Proxy._get_current_object(self)
  File "/Users/c/Envs/mdd_mall/lib/python3.7/site-packages/celery/local.py", line 109, in _get_current_object
    return loc(*self.__args, **self.__kwargs)
  File "/Users/c/Envs/mdd_mall/lib/python3.7/site-packages/celery/app/base.py", line 459, in _task_from_fun
    task.bind(self)  # connects task to this app
  File "/Users/c/Envs/mdd_mall/lib/python3.7/site-packages/celery/app/task.py", line 338, in bind
    setattr(cls, attr_name, conf[config_name])
  File "/Users/c/Envs/mdd_mall/lib/python3.7/site-packages/celery/utils/collections.py", line 437, in __getitem__
    return getitem(k)
  File "/Users/c/Envs/mdd_mall/lib/python3.7/site-packages/celery/utils/collections.py", line 286, in __getitem__
    return mapping[_key]
  File "/Users/c/Envs/mdd_mall/lib/python3.7/collections/__init__.py", line 1021, in __getitem__
    if key in self.data:
  File "/Users/c/Envs/mdd_mall/lib/python3.7/site-packages/kombu/utils/objects.py", line 44, in __get__
    value = obj.__dict__[self.__name__] = self.__get(obj)
  File "/Users/c/Envs/mdd_mall/lib/python3.7/site-packages/celery/app/base.py", line 141, in data
    return self.callback()
  File "/Users/c/Envs/mdd_mall/lib/python3.7/site-packages/celery/app/base.py", line 935, in _finalize_pending_conf
    conf = self._conf = self._load_config()
  File "/Users/c/Envs/mdd_mall/lib/python3.7/site-packages/celery/app/base.py", line 945, in _load_config
    self.loader.config_from_object(self._config_source)
  File "/Users/c/Envs/mdd_mall/lib/python3.7/site-packages/celery/loaders/base.py", line 126, in config_from_object
    obj = self._smart_import(obj, imp=self.import_from_cwd)
  File "/Users/c/Envs/mdd_mall/lib/python3.7/site-packages/celery/loaders/base.py", line 147, in _smart_import
    return symbol_by_name(path, imp=imp)
  File "/Users/c/Envs/mdd_mall/lib/python3.7/site-packages/kombu/utils/imports.py", line 56, in symbol_by_name
    module = imp(module_name, package=package, **kwargs)
  File "/Users/c/Envs/mdd_mall/lib/python3.7/site-packages/celery/loaders/base.py", line 98, in import_from_cwd
    package=package,
  File "/Users/c/Envs/mdd_mall/lib/python3.7/site-packages/celery/utils/imports.py", line 111, in import_from_cwd
    return imp(module, package=package)
  File "/Users/c/Envs/mdd_mall/lib/python3.7/site-packages/celery/loaders/base.py", line 92, in import_module
    return importlib.import_module(module, package=package)
  File "/Users/c/Envs/mdd_mall/lib/python3.7/importlib/__init__.py", line 127, in import_module
    return _bootstrap._gcd_import(name[level:], package, level)
  File "<frozen importlib._bootstrap>", line 1006, in _gcd_import
  File "<frozen importlib._bootstrap>", line 983, in _find_and_load
  File "<frozen importlib._bootstrap>", line 965, in _find_and_load_unlocked
ModuleNotFoundError: No module named 'celery_tasks'
ERROR 2019-04-21 19:56:56,123 basehttp 124 "GET /sms_codes/13818510751/?image_code=6t84&image_code_id=59168e2e-9ac8-4baa-befc-5ef4905239a7 HTTP/1.1" 500 183828
INFO 2019-04-21 19:57:43,111 basehttp 124 "GET /register/ HTTP/1.1" 200 5287
INFO 2019-04-21 19:57:43,164 basehttp 124 "GET /image_codes/6016051c-37db-4219-aecd-bc4df46b3bde/ HTTP/1.1" 200 3464
INFO 2019-04-21 19:57:43,275 basehttp 124 "GET /register/ HTTP/1.1" 200 5287
INFO 2019-04-21 19:57:43,325 basehttp 124 "GET /image_codes/0c1628d3-91b4-4961-a229-7a44233a5d2a/ HTTP/1.1" 200 3181
INFO 2019-04-21 19:57:43,434 basehttp 124 "GET /register/ HTTP/1.1" 200 5287
INFO 2019-04-21 19:57:43,479 basehttp 124 "GET /image_codes/378ea4c9-ad8f-4f2b-8b81-afb105fe8d93/ HTTP/1.1" 200 3210
INFO 2019-04-21 19:57:43,573 basehttp 124 "GET /register/ HTTP/1.1" 200 5287
INFO 2019-04-21 19:57:43,621 basehttp 124 "GET /image_codes/240bcbf3-ffbf-4365-90a8-498b9719f92c/ HTTP/1.1" 200 3118
INFO 2019-04-21 19:57:45,225 basehttp 124 "GET /usernames/admin1/count/ HTTP/1.1" 200 41
INFO 2019-04-21 19:57:49,680 basehttp 124 "GET /mobiles/13818510751/count/ HTTP/1.1" 200 41
INFO 2019-04-21 19:57:53,733 basehttp 124 "GET /sms_codes/13818510751/?image_code=unmf&image_code_id=240bcbf3-ffbf-4365-90a8-498b9719f92c HTTP/1.1" 200 66
INFO 2019-04-21 19:57:53,736 basehttp 124 "GET /mobiles/13818510751/count/ HTTP/1.1" 200 41
INFO 2019-04-21 19:57:53,746 basehttp 124 "GET /image_codes/0f4ac491-c382-48e3-8860-6c652a403984/ HTTP/1.1" 200 3052
INFO 2019-04-21 19:58:05,042 views 56 152226
INFO 2019-04-21 19:58:05,047 basehttp 124 "GET /mobiles/13818510751/count/ HTTP/1.1" 200 41
ERROR 2019-04-21 19:58:05,051 exception 135 Internal Server Error: /sms_codes/13818510751/
Traceback (most recent call last):
  File "/Users/c/Envs/mdd_mall/lib/python3.7/site-packages/celery/local.py", line 317, in _get_current_object
    return object.__getattribute__(self, '__thing')
AttributeError: 'PromiseProxy' object has no attribute '__thing'

During handling of the above exception, another exception occurred:

Traceback (most recent call last):
  File "/Users/c/Envs/mdd_mall/lib/python3.7/site-packages/kombu/utils/objects.py", line 42, in __get__
    return obj.__dict__[self.__name__]
KeyError: 'data'

During handling of the above exception, another exception occurred:

Traceback (most recent call last):
  File "/Users/c/Envs/mdd_mall/lib/python3.7/site-packages/celery/loaders/base.py", line 144, in _smart_import
    return imp(path)
  File "/Users/c/Envs/mdd_mall/lib/python3.7/site-packages/celery/loaders/base.py", line 98, in import_from_cwd
    package=package,
  File "/Users/c/Envs/mdd_mall/lib/python3.7/site-packages/celery/utils/imports.py", line 111, in import_from_cwd
    return imp(module, package=package)
  File "/Users/c/Envs/mdd_mall/lib/python3.7/site-packages/celery/loaders/base.py", line 92, in import_module
    return importlib.import_module(module, package=package)
  File "/Users/c/Envs/mdd_mall/lib/python3.7/importlib/__init__.py", line 127, in import_module
    return _bootstrap._gcd_import(name[level:], package, level)
  File "<frozen importlib._bootstrap>", line 1006, in _gcd_import
  File "<frozen importlib._bootstrap>", line 983, in _find_and_load
  File "<frozen importlib._bootstrap>", line 953, in _find_and_load_unlocked
  File "<frozen importlib._bootstrap>", line 219, in _call_with_frames_removed
  File "<frozen importlib._bootstrap>", line 1006, in _gcd_import
  File "<frozen importlib._bootstrap>", line 983, in _find_and_load
  File "<frozen importlib._bootstrap>", line 965, in _find_and_load_unlocked
ModuleNotFoundError: No module named 'celery_tasks'

During handling of the above exception, another exception occurred:

Traceback (most recent call last):
  File "/Users/c/Envs/mdd_mall/lib/python3.7/site-packages/django/core/handlers/exception.py", line 41, in inner
    response = get_response(request)
  File "/Users/c/Envs/mdd_mall/lib/python3.7/site-packages/django/core/handlers/base.py", line 187, in _get_response
    response = self.process_exception_by_middleware(e, request)
  File "/Users/c/Envs/mdd_mall/lib/python3.7/site-packages/django/core/handlers/base.py", line 185, in _get_response
    response = wrapped_callback(request, *callback_args, **callback_kwargs)
  File "/Users/c/Envs/mdd_mall/lib/python3.7/site-packages/django/views/generic/base.py", line 68, in view
    return self.dispatch(request, *args, **kwargs)
  File "/Users/c/Envs/mdd_mall/lib/python3.7/site-packages/django/views/generic/base.py", line 88, in dispatch
    return handler(request, *args, **kwargs)
  File "/Users/c/Documents/mddproject/mddproject/mdd_mall/mdd_mall/apps/verifications/views.py", line 62, in get
    send_sms_code.delay(mobile,rand_int)
  File "/Users/c/Envs/mdd_mall/lib/python3.7/site-packages/celery/local.py", line 146, in __getattr__
    return getattr(self._get_current_object(), name)
  File "/Users/c/Envs/mdd_mall/lib/python3.7/site-packages/celery/local.py", line 319, in _get_current_object
    return self.__evaluate__()
  File "/Users/c/Envs/mdd_mall/lib/python3.7/site-packages/celery/local.py", line 349, in __evaluate__
    thing = Proxy._get_current_object(self)
  File "/Users/c/Envs/mdd_mall/lib/python3.7/site-packages/celery/local.py", line 109, in _get_current_object
    return loc(*self.__args, **self.__kwargs)
  File "/Users/c/Envs/mdd_mall/lib/python3.7/site-packages/celery/app/base.py", line 459, in _task_from_fun
    task.bind(self)  # connects task to this app
  File "/Users/c/Envs/mdd_mall/lib/python3.7/site-packages/celery/app/task.py", line 338, in bind
    setattr(cls, attr_name, conf[config_name])
  File "/Users/c/Envs/mdd_mall/lib/python3.7/site-packages/celery/utils/collections.py", line 437, in __getitem__
    return getitem(k)
  File "/Users/c/Envs/mdd_mall/lib/python3.7/site-packages/celery/utils/collections.py", line 286, in __getitem__
    return mapping[_key]
  File "/Users/c/Envs/mdd_mall/lib/python3.7/collections/__init__.py", line 1021, in __getitem__
    if key in self.data:
  File "/Users/c/Envs/mdd_mall/lib/python3.7/site-packages/kombu/utils/objects.py", line 44, in __get__
    value = obj.__dict__[self.__name__] = self.__get(obj)
  File "/Users/c/Envs/mdd_mall/lib/python3.7/site-packages/celery/app/base.py", line 141, in data
    return self.callback()
  File "/Users/c/Envs/mdd_mall/lib/python3.7/site-packages/celery/app/base.py", line 935, in _finalize_pending_conf
    conf = self._conf = self._load_config()
  File "/Users/c/Envs/mdd_mall/lib/python3.7/site-packages/celery/app/base.py", line 945, in _load_config
    self.loader.config_from_object(self._config_source)
  File "/Users/c/Envs/mdd_mall/lib/python3.7/site-packages/celery/loaders/base.py", line 126, in config_from_object
    obj = self._smart_import(obj, imp=self.import_from_cwd)
  File "/Users/c/Envs/mdd_mall/lib/python3.7/site-packages/celery/loaders/base.py", line 147, in _smart_import
    return symbol_by_name(path, imp=imp)
  File "/Users/c/Envs/mdd_mall/lib/python3.7/site-packages/kombu/utils/imports.py", line 56, in symbol_by_name
    module = imp(module_name, package=package, **kwargs)
  File "/Users/c/Envs/mdd_mall/lib/python3.7/site-packages/celery/loaders/base.py", line 98, in import_from_cwd
    package=package,
  File "/Users/c/Envs/mdd_mall/lib/python3.7/site-packages/celery/utils/imports.py", line 111, in import_from_cwd
    return imp(module, package=package)
  File "/Users/c/Envs/mdd_mall/lib/python3.7/site-packages/celery/loaders/base.py", line 92, in import_module
    return importlib.import_module(module, package=package)
  File "/Users/c/Envs/mdd_mall/lib/python3.7/importlib/__init__.py", line 127, in import_module
    return _bootstrap._gcd_import(name[level:], package, level)
  File "<frozen importlib._bootstrap>", line 1006, in _gcd_import
  File "<frozen importlib._bootstrap>", line 983, in _find_and_load
  File "<frozen importlib._bootstrap>", line 965, in _find_and_load_unlocked
ModuleNotFoundError: No module named 'celery_tasks'
ERROR 2019-04-21 19:58:05,116 basehttp 124 "GET /sms_codes/13818510751/?image_code=qylx&image_code_id=0f4ac491-c382-48e3-8860-6c652a403984 HTTP/1.1" 500 183828
INFO 2019-04-21 20:05:47,751 basehttp 124 "GET /register/ HTTP/1.1" 200 5287
INFO 2019-04-21 20:05:47,806 basehttp 124 "GET /image_codes/a208bd16-051c-403b-b681-7fb925f0c43d/ HTTP/1.1" 200 3921
INFO 2019-04-21 20:05:48,274 basehttp 124 "GET /register/ HTTP/1.1" 200 5287
INFO 2019-04-21 20:05:48,322 basehttp 124 "GET /image_codes/dbd00f91-3e08-4963-a63b-f0a225aa73c2/ HTTP/1.1" 200 3550
INFO 2019-04-21 20:05:48,450 basehttp 124 "GET /register/ HTTP/1.1" 200 5287
INFO 2019-04-21 20:05:48,499 basehttp 124 "GET /image_codes/f1e7dbf8-a15e-471f-abf7-c5aaa72b02b3/ HTTP/1.1" 200 3153
INFO 2019-04-21 20:05:48,610 basehttp 124 "GET /register/ HTTP/1.1" 200 5287
INFO 2019-04-21 20:05:48,655 basehttp 124 "GET /image_codes/31306f9a-9484-430c-aae4-d5748d7ef003/ HTTP/1.1" 200 3110
INFO 2019-04-21 20:05:48,766 basehttp 124 "GET /register/ HTTP/1.1" 200 5287
INFO 2019-04-21 20:05:48,812 basehttp 124 "GET /image_codes/48c73370-0e72-492d-9fdd-7a28f2fda4a5/ HTTP/1.1" 200 3281
INFO 2019-04-21 20:05:51,886 basehttp 124 "GET /usernames/admin1/count/ HTTP/1.1" 200 41
INFO 2019-04-21 20:05:58,714 basehttp 124 "GET /mobiles/13818510751/count/ HTTP/1.1" 200 41
INFO 2019-04-21 20:06:00,865 views 56 193834
INFO 2019-04-21 20:06:00,870 basehttp 124 "GET /mobiles/13818510751/count/ HTTP/1.1" 200 41
ERROR 2019-04-21 20:06:00,874 exception 135 Internal Server Error: /sms_codes/13818510751/
Traceback (most recent call last):
  File "/Users/c/Envs/mdd_mall/lib/python3.7/site-packages/celery/local.py", line 317, in _get_current_object
    return object.__getattribute__(self, '__thing')
AttributeError: 'PromiseProxy' object has no attribute '__thing'

During handling of the above exception, another exception occurred:

Traceback (most recent call last):
  File "/Users/c/Envs/mdd_mall/lib/python3.7/site-packages/kombu/utils/objects.py", line 42, in __get__
    return obj.__dict__[self.__name__]
KeyError: 'data'

During handling of the above exception, another exception occurred:

Traceback (most recent call last):
  File "/Users/c/Envs/mdd_mall/lib/python3.7/site-packages/celery/loaders/base.py", line 144, in _smart_import
    return imp(path)
  File "/Users/c/Envs/mdd_mall/lib/python3.7/site-packages/celery/loaders/base.py", line 98, in import_from_cwd
    package=package,
  File "/Users/c/Envs/mdd_mall/lib/python3.7/site-packages/celery/utils/imports.py", line 111, in import_from_cwd
    return imp(module, package=package)
  File "/Users/c/Envs/mdd_mall/lib/python3.7/site-packages/celery/loaders/base.py", line 92, in import_module
    return importlib.import_module(module, package=package)
  File "/Users/c/Envs/mdd_mall/lib/python3.7/importlib/__init__.py", line 127, in import_module
    return _bootstrap._gcd_import(name[level:], package, level)
  File "<frozen importlib._bootstrap>", line 1006, in _gcd_import
  File "<frozen importlib._bootstrap>", line 983, in _find_and_load
  File "<frozen importlib._bootstrap>", line 953, in _find_and_load_unlocked
  File "<frozen importlib._bootstrap>", line 219, in _call_with_frames_removed
  File "<frozen importlib._bootstrap>", line 1006, in _gcd_import
  File "<frozen importlib._bootstrap>", line 983, in _find_and_load
  File "<frozen importlib._bootstrap>", line 965, in _find_and_load_unlocked
ModuleNotFoundError: No module named 'celery_tasks'

During handling of the above exception, another exception occurred:

Traceback (most recent call last):
  File "/Users/c/Envs/mdd_mall/lib/python3.7/site-packages/django/core/handlers/exception.py", line 41, in inner
    response = get_response(request)
  File "/Users/c/Envs/mdd_mall/lib/python3.7/site-packages/django/core/handlers/base.py", line 187, in _get_response
    response = self.process_exception_by_middleware(e, request)
  File "/Users/c/Envs/mdd_mall/lib/python3.7/site-packages/django/core/handlers/base.py", line 185, in _get_response
    response = wrapped_callback(request, *callback_args, **callback_kwargs)
  File "/Users/c/Envs/mdd_mall/lib/python3.7/site-packages/django/views/generic/base.py", line 68, in view
    return self.dispatch(request, *args, **kwargs)
  File "/Users/c/Envs/mdd_mall/lib/python3.7/site-packages/django/views/generic/base.py", line 88, in dispatch
    return handler(request, *args, **kwargs)
  File "/Users/c/Documents/mddproject/mddproject/mdd_mall/mdd_mall/apps/verifications/views.py", line 62, in get
    send_sms_code.delay(mobile,rand_int)
  File "/Users/c/Envs/mdd_mall/lib/python3.7/site-packages/celery/local.py", line 146, in __getattr__
    return getattr(self._get_current_object(), name)
  File "/Users/c/Envs/mdd_mall/lib/python3.7/site-packages/celery/local.py", line 319, in _get_current_object
    return self.__evaluate__()
  File "/Users/c/Envs/mdd_mall/lib/python3.7/site-packages/celery/local.py", line 349, in __evaluate__
    thing = Proxy._get_current_object(self)
  File "/Users/c/Envs/mdd_mall/lib/python3.7/site-packages/celery/local.py", line 109, in _get_current_object
    return loc(*self.__args, **self.__kwargs)
  File "/Users/c/Envs/mdd_mall/lib/python3.7/site-packages/celery/app/base.py", line 459, in _task_from_fun
    task.bind(self)  # connects task to this app
  File "/Users/c/Envs/mdd_mall/lib/python3.7/site-packages/celery/app/task.py", line 338, in bind
    setattr(cls, attr_name, conf[config_name])
  File "/Users/c/Envs/mdd_mall/lib/python3.7/site-packages/celery/utils/collections.py", line 437, in __getitem__
    return getitem(k)
  File "/Users/c/Envs/mdd_mall/lib/python3.7/site-packages/celery/utils/collections.py", line 286, in __getitem__
    return mapping[_key]
  File "/Users/c/Envs/mdd_mall/lib/python3.7/collections/__init__.py", line 1021, in __getitem__
    if key in self.data:
  File "/Users/c/Envs/mdd_mall/lib/python3.7/site-packages/kombu/utils/objects.py", line 44, in __get__
    value = obj.__dict__[self.__name__] = self.__get(obj)
  File "/Users/c/Envs/mdd_mall/lib/python3.7/site-packages/celery/app/base.py", line 141, in data
    return self.callback()
  File "/Users/c/Envs/mdd_mall/lib/python3.7/site-packages/celery/app/base.py", line 935, in _finalize_pending_conf
    conf = self._conf = self._load_config()
  File "/Users/c/Envs/mdd_mall/lib/python3.7/site-packages/celery/app/base.py", line 945, in _load_config
    self.loader.config_from_object(self._config_source)
  File "/Users/c/Envs/mdd_mall/lib/python3.7/site-packages/celery/loaders/base.py", line 126, in config_from_object
    obj = self._smart_import(obj, imp=self.import_from_cwd)
  File "/Users/c/Envs/mdd_mall/lib/python3.7/site-packages/celery/loaders/base.py", line 147, in _smart_import
    return symbol_by_name(path, imp=imp)
  File "/Users/c/Envs/mdd_mall/lib/python3.7/site-packages/kombu/utils/imports.py", line 56, in symbol_by_name
    module = imp(module_name, package=package, **kwargs)
  File "/Users/c/Envs/mdd_mall/lib/python3.7/site-packages/celery/loaders/base.py", line 98, in import_from_cwd
    package=package,
  File "/Users/c/Envs/mdd_mall/lib/python3.7/site-packages/celery/utils/imports.py", line 111, in import_from_cwd
    return imp(module, package=package)
  File "/Users/c/Envs/mdd_mall/lib/python3.7/site-packages/celery/loaders/base.py", line 92, in import_module
    return importlib.import_module(module, package=package)
  File "/Users/c/Envs/mdd_mall/lib/python3.7/importlib/__init__.py", line 127, in import_module
    return _bootstrap._gcd_import(name[level:], package, level)
  File "<frozen importlib._bootstrap>", line 1006, in _gcd_import
  File "<frozen importlib._bootstrap>", line 983, in _find_and_load
  File "<frozen importlib._bootstrap>", line 965, in _find_and_load_unlocked
ModuleNotFoundError: No module named 'celery_tasks'
ERROR 2019-04-21 20:06:00,939 basehttp 124 "GET /sms_codes/13818510751/?image_code=qcy3&image_code_id=48c73370-0e72-492d-9fdd-7a28f2fda4a5 HTTP/1.1" 500 183828
INFO 2019-04-21 20:26:19,138 basehttp 124 "GET /register/ HTTP/1.1" 200 5287
INFO 2019-04-21 20:26:19,189 basehttp 124 "GET /image_codes/3e97317e-9176-4897-a061-9c3286f7892a/ HTTP/1.1" 200 3313
INFO 2019-04-21 20:26:19,296 basehttp 124 "GET /register/ HTTP/1.1" 200 5287
INFO 2019-04-21 20:26:19,340 basehttp 124 "GET /image_codes/6092be00-1ad8-44fb-be77-04a59000c296/ HTTP/1.1" 200 3208
INFO 2019-04-21 20:26:19,473 basehttp 124 "GET /register/ HTTP/1.1" 200 5287
INFO 2019-04-21 20:26:19,519 basehttp 124 "GET /image_codes/bf8f08d8-c200-47cd-ad7d-f4aa763c44c4/ HTTP/1.1" 200 2991
INFO 2019-04-21 20:26:19,639 basehttp 124 "GET /register/ HTTP/1.1" 200 5287
INFO 2019-04-21 20:26:19,684 basehttp 124 "GET /image_codes/366ebf52-5e87-43df-905a-486c7eebbfff/ HTTP/1.1" 200 3152
INFO 2019-04-21 20:26:19,782 basehttp 124 "GET /register/ HTTP/1.1" 200 5287
INFO 2019-04-21 20:26:19,828 basehttp 124 "GET /image_codes/d63ab180-148d-406f-acdf-66f495062ccb/ HTTP/1.1" 200 3306
INFO 2019-04-21 20:26:19,932 basehttp 124 "GET /register/ HTTP/1.1" 200 5287
INFO 2019-04-21 20:26:19,980 basehttp 124 "GET /image_codes/ecb3b5e8-9dbc-4bc4-ae7f-6d4a35dd84d0/ HTTP/1.1" 200 3205
INFO 2019-04-21 20:26:25,012 basehttp 124 "GET /usernames/admina/count/ HTTP/1.1" 200 41
INFO 2019-04-21 20:26:30,296 basehttp 124 "GET /mobiles/13818510751/count/ HTTP/1.1" 200 41
INFO 2019-04-21 20:26:35,275 basehttp 124 "GET /image_codes/826cda42-4ee5-460d-80d0-c2a011942595/ HTTP/1.1" 200 3144
INFO 2019-04-21 20:26:38,828 views 56 560110
INFO 2019-04-21 20:26:38,832 basehttp 124 "GET /mobiles/13818510751/count/ HTTP/1.1" 200 41
ERROR 2019-04-21 20:26:38,836 exception 135 Internal Server Error: /sms_codes/13818510751/
Traceback (most recent call last):
  File "/Users/c/Envs/mdd_mall/lib/python3.7/site-packages/celery/local.py", line 317, in _get_current_object
    return object.__getattribute__(self, '__thing')
AttributeError: 'PromiseProxy' object has no attribute '__thing'

During handling of the above exception, another exception occurred:

Traceback (most recent call last):
  File "/Users/c/Envs/mdd_mall/lib/python3.7/site-packages/kombu/utils/objects.py", line 42, in __get__
    return obj.__dict__[self.__name__]
KeyError: 'data'

During handling of the above exception, another exception occurred:

Traceback (most recent call last):
  File "/Users/c/Envs/mdd_mall/lib/python3.7/site-packages/celery/loaders/base.py", line 144, in _smart_import
    return imp(path)
  File "/Users/c/Envs/mdd_mall/lib/python3.7/site-packages/celery/loaders/base.py", line 98, in import_from_cwd
    package=package,
  File "/Users/c/Envs/mdd_mall/lib/python3.7/site-packages/celery/utils/imports.py", line 111, in import_from_cwd
    return imp(module, package=package)
  File "/Users/c/Envs/mdd_mall/lib/python3.7/site-packages/celery/loaders/base.py", line 92, in import_module
    return importlib.import_module(module, package=package)
  File "/Users/c/Envs/mdd_mall/lib/python3.7/importlib/__init__.py", line 127, in import_module
    return _bootstrap._gcd_import(name[level:], package, level)
  File "<frozen importlib._bootstrap>", line 1006, in _gcd_import
  File "<frozen importlib._bootstrap>", line 983, in _find_and_load
  File "<frozen importlib._bootstrap>", line 953, in _find_and_load_unlocked
  File "<frozen importlib._bootstrap>", line 219, in _call_with_frames_removed
  File "<frozen importlib._bootstrap>", line 1006, in _gcd_import
  File "<frozen importlib._bootstrap>", line 983, in _find_and_load
  File "<frozen importlib._bootstrap>", line 965, in _find_and_load_unlocked
ModuleNotFoundError: No module named 'celtasks'

During handling of the above exception, another exception occurred:

Traceback (most recent call last):
  File "/Users/c/Envs/mdd_mall/lib/python3.7/site-packages/django/core/handlers/exception.py", line 41, in inner
    response = get_response(request)
  File "/Users/c/Envs/mdd_mall/lib/python3.7/site-packages/django/core/handlers/base.py", line 187, in _get_response
    response = self.process_exception_by_middleware(e, request)
  File "/Users/c/Envs/mdd_mall/lib/python3.7/site-packages/django/core/handlers/base.py", line 185, in _get_response
    response = wrapped_callback(request, *callback_args, **callback_kwargs)
  File "/Users/c/Envs/mdd_mall/lib/python3.7/site-packages/django/views/generic/base.py", line 68, in view
    return self.dispatch(request, *args, **kwargs)
  File "/Users/c/Envs/mdd_mall/lib/python3.7/site-packages/django/views/generic/base.py", line 88, in dispatch
    return handler(request, *args, **kwargs)
  File "/Users/c/Documents/mddproject/mddproject/mdd_mall/mdd_mall/apps/verifications/views.py", line 62, in get
    send_sms_code.delay(mobile,rand_int)
  File "/Users/c/Envs/mdd_mall/lib/python3.7/site-packages/celery/local.py", line 146, in __getattr__
    return getattr(self._get_current_object(), name)
  File "/Users/c/Envs/mdd_mall/lib/python3.7/site-packages/celery/local.py", line 319, in _get_current_object
    return self.__evaluate__()
  File "/Users/c/Envs/mdd_mall/lib/python3.7/site-packages/celery/local.py", line 349, in __evaluate__
    thing = Proxy._get_current_object(self)
  File "/Users/c/Envs/mdd_mall/lib/python3.7/site-packages/celery/local.py", line 109, in _get_current_object
    return loc(*self.__args, **self.__kwargs)
  File "/Users/c/Envs/mdd_mall/lib/python3.7/site-packages/celery/app/base.py", line 459, in _task_from_fun
    task.bind(self)  # connects task to this app
  File "/Users/c/Envs/mdd_mall/lib/python3.7/site-packages/celery/app/task.py", line 338, in bind
    setattr(cls, attr_name, conf[config_name])
  File "/Users/c/Envs/mdd_mall/lib/python3.7/site-packages/celery/utils/collections.py", line 437, in __getitem__
    return getitem(k)
  File "/Users/c/Envs/mdd_mall/lib/python3.7/site-packages/celery/utils/collections.py", line 286, in __getitem__
    return mapping[_key]
  File "/Users/c/Envs/mdd_mall/lib/python3.7/collections/__init__.py", line 1021, in __getitem__
    if key in self.data:
  File "/Users/c/Envs/mdd_mall/lib/python3.7/site-packages/kombu/utils/objects.py", line 44, in __get__
    value = obj.__dict__[self.__name__] = self.__get(obj)
  File "/Users/c/Envs/mdd_mall/lib/python3.7/site-packages/celery/app/base.py", line 141, in data
    return self.callback()
  File "/Users/c/Envs/mdd_mall/lib/python3.7/site-packages/celery/app/base.py", line 935, in _finalize_pending_conf
    conf = self._conf = self._load_config()
  File "/Users/c/Envs/mdd_mall/lib/python3.7/site-packages/celery/app/base.py", line 945, in _load_config
    self.loader.config_from_object(self._config_source)
  File "/Users/c/Envs/mdd_mall/lib/python3.7/site-packages/celery/loaders/base.py", line 126, in config_from_object
    obj = self._smart_import(obj, imp=self.import_from_cwd)
  File "/Users/c/Envs/mdd_mall/lib/python3.7/site-packages/celery/loaders/base.py", line 147, in _smart_import
    return symbol_by_name(path, imp=imp)
  File "/Users/c/Envs/mdd_mall/lib/python3.7/site-packages/kombu/utils/imports.py", line 56, in symbol_by_name
    module = imp(module_name, package=package, **kwargs)
  File "/Users/c/Envs/mdd_mall/lib/python3.7/site-packages/celery/loaders/base.py", line 98, in import_from_cwd
    package=package,
  File "/Users/c/Envs/mdd_mall/lib/python3.7/site-packages/celery/utils/imports.py", line 111, in import_from_cwd
    return imp(module, package=package)
  File "/Users/c/Envs/mdd_mall/lib/python3.7/site-packages/celery/loaders/base.py", line 92, in import_module
    return importlib.import_module(module, package=package)
  File "/Users/c/Envs/mdd_mall/lib/python3.7/importlib/__init__.py", line 127, in import_module
    return _bootstrap._gcd_import(name[level:], package, level)
  File "<frozen importlib._bootstrap>", line 1006, in _gcd_import
  File "<frozen importlib._bootstrap>", line 983, in _find_and_load
  File "<frozen importlib._bootstrap>", line 965, in _find_and_load_unlocked
ModuleNotFoundError: No module named 'celtasks'
ERROR 2019-04-21 20:26:38,901 basehttp 124 "GET /sms_codes/13818510751/?image_code=ptld&image_code_id=826cda42-4ee5-460d-80d0-c2a011942595 HTTP/1.1" 500 183712
INFO 2019-04-21 20:30:15,172 basehttp 124 "GET /image_codes/ddb8ac1b-02bd-47a8-b5f5-5885d59eb593/ HTTP/1.1" 200 2981
INFO 2019-04-21 20:30:18,977 views 56 440129
INFO 2019-04-21 20:30:18,983 basehttp 124 "GET /mobiles/13818510751/count/ HTTP/1.1" 200 41
ERROR 2019-04-21 20:30:18,986 exception 135 Internal Server Error: /sms_codes/13818510751/
Traceback (most recent call last):
  File "/Users/c/Envs/mdd_mall/lib/python3.7/site-packages/celery/local.py", line 317, in _get_current_object
    return object.__getattribute__(self, '__thing')
AttributeError: 'PromiseProxy' object has no attribute '__thing'

During handling of the above exception, another exception occurred:

Traceback (most recent call last):
  File "/Users/c/Envs/mdd_mall/lib/python3.7/site-packages/kombu/utils/objects.py", line 42, in __get__
    return obj.__dict__[self.__name__]
KeyError: 'data'

During handling of the above exception, another exception occurred:

Traceback (most recent call last):
  File "/Users/c/Envs/mdd_mall/lib/python3.7/site-packages/celery/loaders/base.py", line 144, in _smart_import
    return imp(path)
  File "/Users/c/Envs/mdd_mall/lib/python3.7/site-packages/celery/loaders/base.py", line 98, in import_from_cwd
    package=package,
  File "/Users/c/Envs/mdd_mall/lib/python3.7/site-packages/celery/utils/imports.py", line 111, in import_from_cwd
    return imp(module, package=package)
  File "/Users/c/Envs/mdd_mall/lib/python3.7/site-packages/celery/loaders/base.py", line 92, in import_module
    return importlib.import_module(module, package=package)
  File "/Users/c/Envs/mdd_mall/lib/python3.7/importlib/__init__.py", line 127, in import_module
    return _bootstrap._gcd_import(name[level:], package, level)
  File "<frozen importlib._bootstrap>", line 1006, in _gcd_import
  File "<frozen importlib._bootstrap>", line 983, in _find_and_load
  File "<frozen importlib._bootstrap>", line 953, in _find_and_load_unlocked
  File "<frozen importlib._bootstrap>", line 219, in _call_with_frames_removed
  File "<frozen importlib._bootstrap>", line 1006, in _gcd_import
  File "<frozen importlib._bootstrap>", line 983, in _find_and_load
  File "<frozen importlib._bootstrap>", line 965, in _find_and_load_unlocked
ModuleNotFoundError: No module named 'celtasks'

During handling of the above exception, another exception occurred:

Traceback (most recent call last):
  File "/Users/c/Envs/mdd_mall/lib/python3.7/site-packages/django/core/handlers/exception.py", line 41, in inner
    response = get_response(request)
  File "/Users/c/Envs/mdd_mall/lib/python3.7/site-packages/django/core/handlers/base.py", line 187, in _get_response
    response = self.process_exception_by_middleware(e, request)
  File "/Users/c/Envs/mdd_mall/lib/python3.7/site-packages/django/core/handlers/base.py", line 185, in _get_response
    response = wrapped_callback(request, *callback_args, **callback_kwargs)
  File "/Users/c/Envs/mdd_mall/lib/python3.7/site-packages/django/views/generic/base.py", line 68, in view
    return self.dispatch(request, *args, **kwargs)
  File "/Users/c/Envs/mdd_mall/lib/python3.7/site-packages/django/views/generic/base.py", line 88, in dispatch
    return handler(request, *args, **kwargs)
  File "/Users/c/Documents/mddproject/mddproject/mdd_mall/mdd_mall/apps/verifications/views.py", line 62, in get
    send_sms_code.delay(mobile,rand_int)
  File "/Users/c/Envs/mdd_mall/lib/python3.7/site-packages/celery/local.py", line 146, in __getattr__
    return getattr(self._get_current_object(), name)
  File "/Users/c/Envs/mdd_mall/lib/python3.7/site-packages/celery/local.py", line 319, in _get_current_object
    return self.__evaluate__()
  File "/Users/c/Envs/mdd_mall/lib/python3.7/site-packages/celery/local.py", line 349, in __evaluate__
    thing = Proxy._get_current_object(self)
  File "/Users/c/Envs/mdd_mall/lib/python3.7/site-packages/celery/local.py", line 109, in _get_current_object
    return loc(*self.__args, **self.__kwargs)
  File "/Users/c/Envs/mdd_mall/lib/python3.7/site-packages/celery/app/base.py", line 459, in _task_from_fun
    task.bind(self)  # connects task to this app
  File "/Users/c/Envs/mdd_mall/lib/python3.7/site-packages/celery/app/task.py", line 338, in bind
    setattr(cls, attr_name, conf[config_name])
  File "/Users/c/Envs/mdd_mall/lib/python3.7/site-packages/celery/utils/collections.py", line 437, in __getitem__
    return getitem(k)
  File "/Users/c/Envs/mdd_mall/lib/python3.7/site-packages/celery/utils/collections.py", line 286, in __getitem__
    return mapping[_key]
  File "/Users/c/Envs/mdd_mall/lib/python3.7/collections/__init__.py", line 1021, in __getitem__
    if key in self.data:
  File "/Users/c/Envs/mdd_mall/lib/python3.7/site-packages/kombu/utils/objects.py", line 44, in __get__
    value = obj.__dict__[self.__name__] = self.__get(obj)
  File "/Users/c/Envs/mdd_mall/lib/python3.7/site-packages/celery/app/base.py", line 141, in data
    return self.callback()
  File "/Users/c/Envs/mdd_mall/lib/python3.7/site-packages/celery/app/base.py", line 935, in _finalize_pending_conf
    conf = self._conf = self._load_config()
  File "/Users/c/Envs/mdd_mall/lib/python3.7/site-packages/celery/app/base.py", line 945, in _load_config
    self.loader.config_from_object(self._config_source)
  File "/Users/c/Envs/mdd_mall/lib/python3.7/site-packages/celery/loaders/base.py", line 126, in config_from_object
    obj = self._smart_import(obj, imp=self.import_from_cwd)
  File "/Users/c/Envs/mdd_mall/lib/python3.7/site-packages/celery/loaders/base.py", line 147, in _smart_import
    return symbol_by_name(path, imp=imp)
  File "/Users/c/Envs/mdd_mall/lib/python3.7/site-packages/kombu/utils/imports.py", line 56, in symbol_by_name
    module = imp(module_name, package=package, **kwargs)
  File "/Users/c/Envs/mdd_mall/lib/python3.7/site-packages/celery/loaders/base.py", line 98, in import_from_cwd
    package=package,
  File "/Users/c/Envs/mdd_mall/lib/python3.7/site-packages/celery/utils/imports.py", line 111, in import_from_cwd
    return imp(module, package=package)
  File "/Users/c/Envs/mdd_mall/lib/python3.7/site-packages/celery/loaders/base.py", line 92, in import_module
    return importlib.import_module(module, package=package)
  File "/Users/c/Envs/mdd_mall/lib/python3.7/importlib/__init__.py", line 127, in import_module
    return _bootstrap._gcd_import(name[level:], package, level)
  File "<frozen importlib._bootstrap>", line 1006, in _gcd_import
  File "<frozen importlib._bootstrap>", line 983, in _find_and_load
  File "<frozen importlib._bootstrap>", line 965, in _find_and_load_unlocked
ModuleNotFoundError: No module named 'celtasks'
ERROR 2019-04-21 20:30:19,050 basehttp 124 "GET /sms_codes/13818510751/?image_code=ormk&image_code_id=ddb8ac1b-02bd-47a8-b5f5-5885d59eb593 HTTP/1.1" 500 183712
INFO 2019-04-21 20:35:53,748 basehttp 124 "GET /image_codes/51d4c5f1-28cd-44a9-b7dc-f32e82f9f782/ HTTP/1.1" 200 3606
INFO 2019-04-21 20:35:57,277 views 56 266692
INFO 2019-04-21 20:35:57,281 basehttp 124 "GET /mobiles/13818510751/count/ HTTP/1.1" 200 41
ERROR 2019-04-21 20:35:57,284 exception 135 Internal Server Error: /sms_codes/13818510751/
Traceback (most recent call last):
  File "/Users/c/Envs/mdd_mall/lib/python3.7/site-packages/celery/local.py", line 317, in _get_current_object
    return object.__getattribute__(self, '__thing')
AttributeError: 'PromiseProxy' object has no attribute '__thing'

During handling of the above exception, another exception occurred:

Traceback (most recent call last):
  File "/Users/c/Envs/mdd_mall/lib/python3.7/site-packages/kombu/utils/objects.py", line 42, in __get__
    return obj.__dict__[self.__name__]
KeyError: 'data'

During handling of the above exception, another exception occurred:

Traceback (most recent call last):
  File "/Users/c/Envs/mdd_mall/lib/python3.7/site-packages/celery/loaders/base.py", line 144, in _smart_import
    return imp(path)
  File "/Users/c/Envs/mdd_mall/lib/python3.7/site-packages/celery/loaders/base.py", line 98, in import_from_cwd
    package=package,
  File "/Users/c/Envs/mdd_mall/lib/python3.7/site-packages/celery/utils/imports.py", line 111, in import_from_cwd
    return imp(module, package=package)
  File "/Users/c/Envs/mdd_mall/lib/python3.7/site-packages/celery/loaders/base.py", line 92, in import_module
    return importlib.import_module(module, package=package)
  File "/Users/c/Envs/mdd_mall/lib/python3.7/importlib/__init__.py", line 127, in import_module
    return _bootstrap._gcd_import(name[level:], package, level)
  File "<frozen importlib._bootstrap>", line 1006, in _gcd_import
  File "<frozen importlib._bootstrap>", line 983, in _find_and_load
  File "<frozen importlib._bootstrap>", line 953, in _find_and_load_unlocked
  File "<frozen importlib._bootstrap>", line 219, in _call_with_frames_removed
  File "<frozen importlib._bootstrap>", line 1006, in _gcd_import
  File "<frozen importlib._bootstrap>", line 983, in _find_and_load
  File "<frozen importlib._bootstrap>", line 965, in _find_and_load_unlocked
ModuleNotFoundError: No module named 'celtasks'

During handling of the above exception, another exception occurred:

Traceback (most recent call last):
  File "/Users/c/Envs/mdd_mall/lib/python3.7/site-packages/django/core/handlers/exception.py", line 41, in inner
    response = get_response(request)
  File "/Users/c/Envs/mdd_mall/lib/python3.7/site-packages/django/core/handlers/base.py", line 187, in _get_response
    response = self.process_exception_by_middleware(e, request)
  File "/Users/c/Envs/mdd_mall/lib/python3.7/site-packages/django/core/handlers/base.py", line 185, in _get_response
    response = wrapped_callback(request, *callback_args, **callback_kwargs)
  File "/Users/c/Envs/mdd_mall/lib/python3.7/site-packages/django/views/generic/base.py", line 68, in view
    return self.dispatch(request, *args, **kwargs)
  File "/Users/c/Envs/mdd_mall/lib/python3.7/site-packages/django/views/generic/base.py", line 88, in dispatch
    return handler(request, *args, **kwargs)
  File "/Users/c/Documents/mddproject/mddproject/mdd_mall/mdd_mall/apps/verifications/views.py", line 62, in get
    send_sms_code.delay(mobile,rand_int)
  File "/Users/c/Envs/mdd_mall/lib/python3.7/site-packages/celery/local.py", line 146, in __getattr__
    return getattr(self._get_current_object(), name)
  File "/Users/c/Envs/mdd_mall/lib/python3.7/site-packages/celery/local.py", line 319, in _get_current_object
    return self.__evaluate__()
  File "/Users/c/Envs/mdd_mall/lib/python3.7/site-packages/celery/local.py", line 349, in __evaluate__
    thing = Proxy._get_current_object(self)
  File "/Users/c/Envs/mdd_mall/lib/python3.7/site-packages/celery/local.py", line 109, in _get_current_object
    return loc(*self.__args, **self.__kwargs)
  File "/Users/c/Envs/mdd_mall/lib/python3.7/site-packages/celery/app/base.py", line 459, in _task_from_fun
    task.bind(self)  # connects task to this app
  File "/Users/c/Envs/mdd_mall/lib/python3.7/site-packages/celery/app/task.py", line 338, in bind
    setattr(cls, attr_name, conf[config_name])
  File "/Users/c/Envs/mdd_mall/lib/python3.7/site-packages/celery/utils/collections.py", line 437, in __getitem__
    return getitem(k)
  File "/Users/c/Envs/mdd_mall/lib/python3.7/site-packages/celery/utils/collections.py", line 286, in __getitem__
    return mapping[_key]
  File "/Users/c/Envs/mdd_mall/lib/python3.7/collections/__init__.py", line 1021, in __getitem__
    if key in self.data:
  File "/Users/c/Envs/mdd_mall/lib/python3.7/site-packages/kombu/utils/objects.py", line 44, in __get__
    value = obj.__dict__[self.__name__] = self.__get(obj)
  File "/Users/c/Envs/mdd_mall/lib/python3.7/site-packages/celery/app/base.py", line 141, in data
    return self.callback()
  File "/Users/c/Envs/mdd_mall/lib/python3.7/site-packages/celery/app/base.py", line 935, in _finalize_pending_conf
    conf = self._conf = self._load_config()
  File "/Users/c/Envs/mdd_mall/lib/python3.7/site-packages/celery/app/base.py", line 945, in _load_config
    self.loader.config_from_object(self._config_source)
  File "/Users/c/Envs/mdd_mall/lib/python3.7/site-packages/celery/loaders/base.py", line 126, in config_from_object
    obj = self._smart_import(obj, imp=self.import_from_cwd)
  File "/Users/c/Envs/mdd_mall/lib/python3.7/site-packages/celery/loaders/base.py", line 147, in _smart_import
    return symbol_by_name(path, imp=imp)
  File "/Users/c/Envs/mdd_mall/lib/python3.7/site-packages/kombu/utils/imports.py", line 56, in symbol_by_name
    module = imp(module_name, package=package, **kwargs)
  File "/Users/c/Envs/mdd_mall/lib/python3.7/site-packages/celery/loaders/base.py", line 98, in import_from_cwd
    package=package,
  File "/Users/c/Envs/mdd_mall/lib/python3.7/site-packages/celery/utils/imports.py", line 111, in import_from_cwd
    return imp(module, package=package)
  File "/Users/c/Envs/mdd_mall/lib/python3.7/site-packages/celery/loaders/base.py", line 92, in import_module
    return importlib.import_module(module, package=package)
  File "/Users/c/Envs/mdd_mall/lib/python3.7/importlib/__init__.py", line 127, in import_module
    return _bootstrap._gcd_import(name[level:], package, level)
  File "<frozen importlib._bootstrap>", line 1006, in _gcd_import
  File "<frozen importlib._bootstrap>", line 983, in _find_and_load
  File "<frozen importlib._bootstrap>", line 965, in _find_and_load_unlocked
ModuleNotFoundError: No module named 'celtasks'
ERROR 2019-04-21 20:35:57,345 basehttp 124 "GET /sms_codes/13818510751/?image_code=mxuw&image_code_id=51d4c5f1-28cd-44a9-b7dc-f32e82f9f782 HTTP/1.1" 500 183712
INFO 2019-04-21 20:48:26,620 basehttp 124 "GET /register/ HTTP/1.1" 200 5287
INFO 2019-04-21 20:48:26,695 basehttp 124 "GET /image_codes/86dce7c9-5989-4236-a238-92ff7ab862ba/ HTTP/1.1" 200 3203
INFO 2019-04-21 20:48:26,778 basehttp 124 "GET /register/ HTTP/1.1" 200 5287
INFO 2019-04-21 20:48:26,821 basehttp 124 "GET /image_codes/ad15c076-9ab7-4788-83aa-92fd395f7e85/ HTTP/1.1" 200 2948
INFO 2019-04-21 20:48:26,953 basehttp 124 "GET /register/ HTTP/1.1" 200 5287
INFO 2019-04-21 20:48:26,997 basehttp 124 "GET /image_codes/8c06a7a5-e929-4b98-b683-b690ebb7f6ca/ HTTP/1.1" 200 3245
INFO 2019-04-21 20:48:27,117 basehttp 124 "GET /register/ HTTP/1.1" 200 5287
INFO 2019-04-21 20:48:27,160 basehttp 124 "GET /image_codes/27741adb-4cb5-4d6c-8073-e1ef2424f473/ HTTP/1.1" 200 3216
INFO 2019-04-21 20:48:27,270 basehttp 124 "GET /register/ HTTP/1.1" 200 5287
INFO 2019-04-21 20:48:27,319 basehttp 124 "GET /image_codes/b077f0a8-5d68-40aa-9392-2699d08b98c0/ HTTP/1.1" 200 3541
INFO 2019-04-21 20:48:28,905 basehttp 124 "GET /usernames/admin1/count/ HTTP/1.1" 200 41
INFO 2019-04-21 20:48:33,879 basehttp 124 "GET /mobiles/13818510751/count/ HTTP/1.1" 200 41
INFO 2019-04-21 20:48:37,020 views 56 906235
INFO 2019-04-21 20:48:37,024 basehttp 124 "GET /mobiles/13818510751/count/ HTTP/1.1" 200 41
ERROR 2019-04-21 20:48:37,028 exception 135 Internal Server Error: /sms_codes/13818510751/
Traceback (most recent call last):
  File "/Users/c/Envs/mdd_mall/lib/python3.7/site-packages/celery/local.py", line 317, in _get_current_object
    return object.__getattribute__(self, '__thing')
AttributeError: 'PromiseProxy' object has no attribute '__thing'

During handling of the above exception, another exception occurred:

Traceback (most recent call last):
  File "/Users/c/Envs/mdd_mall/lib/python3.7/site-packages/kombu/utils/objects.py", line 42, in __get__
    return obj.__dict__[self.__name__]
KeyError: 'data'

During handling of the above exception, another exception occurred:

Traceback (most recent call last):
  File "/Users/c/Envs/mdd_mall/lib/python3.7/site-packages/celery/loaders/base.py", line 144, in _smart_import
    return imp(path)
  File "/Users/c/Envs/mdd_mall/lib/python3.7/site-packages/celery/loaders/base.py", line 98, in import_from_cwd
    package=package,
  File "/Users/c/Envs/mdd_mall/lib/python3.7/site-packages/celery/utils/imports.py", line 111, in import_from_cwd
    return imp(module, package=package)
  File "/Users/c/Envs/mdd_mall/lib/python3.7/site-packages/celery/loaders/base.py", line 92, in import_module
    return importlib.import_module(module, package=package)
  File "/Users/c/Envs/mdd_mall/lib/python3.7/importlib/__init__.py", line 127, in import_module
    return _bootstrap._gcd_import(name[level:], package, level)
  File "<frozen importlib._bootstrap>", line 1006, in _gcd_import
  File "<frozen importlib._bootstrap>", line 983, in _find_and_load
  File "<frozen importlib._bootstrap>", line 953, in _find_and_load_unlocked
  File "<frozen importlib._bootstrap>", line 219, in _call_with_frames_removed
  File "<frozen importlib._bootstrap>", line 1006, in _gcd_import
  File "<frozen importlib._bootstrap>", line 983, in _find_and_load
  File "<frozen importlib._bootstrap>", line 965, in _find_and_load_unlocked
ModuleNotFoundError: No module named 'celtasks'

During handling of the above exception, another exception occurred:

Traceback (most recent call last):
  File "/Users/c/Envs/mdd_mall/lib/python3.7/site-packages/django/core/handlers/exception.py", line 41, in inner
    response = get_response(request)
  File "/Users/c/Envs/mdd_mall/lib/python3.7/site-packages/django/core/handlers/base.py", line 187, in _get_response
    response = self.process_exception_by_middleware(e, request)
  File "/Users/c/Envs/mdd_mall/lib/python3.7/site-packages/django/core/handlers/base.py", line 185, in _get_response
    response = wrapped_callback(request, *callback_args, **callback_kwargs)
  File "/Users/c/Envs/mdd_mall/lib/python3.7/site-packages/django/views/generic/base.py", line 68, in view
    return self.dispatch(request, *args, **kwargs)
  File "/Users/c/Envs/mdd_mall/lib/python3.7/site-packages/django/views/generic/base.py", line 88, in dispatch
    return handler(request, *args, **kwargs)
  File "/Users/c/Documents/mddproject/mddproject/mdd_mall/mdd_mall/apps/verifications/views.py", line 62, in get
    send_sms_code.delay(mobile,rand_int)
  File "/Users/c/Envs/mdd_mall/lib/python3.7/site-packages/celery/local.py", line 146, in __getattr__
    return getattr(self._get_current_object(), name)
  File "/Users/c/Envs/mdd_mall/lib/python3.7/site-packages/celery/local.py", line 319, in _get_current_object
    return self.__evaluate__()
  File "/Users/c/Envs/mdd_mall/lib/python3.7/site-packages/celery/local.py", line 349, in __evaluate__
    thing = Proxy._get_current_object(self)
  File "/Users/c/Envs/mdd_mall/lib/python3.7/site-packages/celery/local.py", line 109, in _get_current_object
    return loc(*self.__args, **self.__kwargs)
  File "/Users/c/Envs/mdd_mall/lib/python3.7/site-packages/celery/app/base.py", line 459, in _task_from_fun
    task.bind(self)  # connects task to this app
  File "/Users/c/Envs/mdd_mall/lib/python3.7/site-packages/celery/app/task.py", line 338, in bind
    setattr(cls, attr_name, conf[config_name])
  File "/Users/c/Envs/mdd_mall/lib/python3.7/site-packages/celery/utils/collections.py", line 437, in __getitem__
    return getitem(k)
  File "/Users/c/Envs/mdd_mall/lib/python3.7/site-packages/celery/utils/collections.py", line 286, in __getitem__
    return mapping[_key]
  File "/Users/c/Envs/mdd_mall/lib/python3.7/collections/__init__.py", line 1021, in __getitem__
    if key in self.data:
  File "/Users/c/Envs/mdd_mall/lib/python3.7/site-packages/kombu/utils/objects.py", line 44, in __get__
    value = obj.__dict__[self.__name__] = self.__get(obj)
  File "/Users/c/Envs/mdd_mall/lib/python3.7/site-packages/celery/app/base.py", line 141, in data
    return self.callback()
  File "/Users/c/Envs/mdd_mall/lib/python3.7/site-packages/celery/app/base.py", line 935, in _finalize_pending_conf
    conf = self._conf = self._load_config()
  File "/Users/c/Envs/mdd_mall/lib/python3.7/site-packages/celery/app/base.py", line 945, in _load_config
    self.loader.config_from_object(self._config_source)
  File "/Users/c/Envs/mdd_mall/lib/python3.7/site-packages/celery/loaders/base.py", line 126, in config_from_object
    obj = self._smart_import(obj, imp=self.import_from_cwd)
  File "/Users/c/Envs/mdd_mall/lib/python3.7/site-packages/celery/loaders/base.py", line 147, in _smart_import
    return symbol_by_name(path, imp=imp)
  File "/Users/c/Envs/mdd_mall/lib/python3.7/site-packages/kombu/utils/imports.py", line 56, in symbol_by_name
    module = imp(module_name, package=package, **kwargs)
  File "/Users/c/Envs/mdd_mall/lib/python3.7/site-packages/celery/loaders/base.py", line 98, in import_from_cwd
    package=package,
  File "/Users/c/Envs/mdd_mall/lib/python3.7/site-packages/celery/utils/imports.py", line 111, in import_from_cwd
    return imp(module, package=package)
  File "/Users/c/Envs/mdd_mall/lib/python3.7/site-packages/celery/loaders/base.py", line 92, in import_module
    return importlib.import_module(module, package=package)
  File "/Users/c/Envs/mdd_mall/lib/python3.7/importlib/__init__.py", line 127, in import_module
    return _bootstrap._gcd_import(name[level:], package, level)
  File "<frozen importlib._bootstrap>", line 1006, in _gcd_import
  File "<frozen importlib._bootstrap>", line 983, in _find_and_load
  File "<frozen importlib._bootstrap>", line 965, in _find_and_load_unlocked
ModuleNotFoundError: No module named 'celtasks'
ERROR 2019-04-21 20:48:37,091 basehttp 124 "GET /sms_codes/13818510751/?image_code=mg6l&image_code_id=b077f0a8-5d68-40aa-9392-2699d08b98c0 HTTP/1.1" 500 183712
INFO 2019-04-21 20:57:51,805 basehttp 124 "GET /register/ HTTP/1.1" 200 5287
INFO 2019-04-21 20:57:51,856 basehttp 124 "GET /image_codes/217d5304-ef7c-431a-bf9f-f381f8e98b9e/ HTTP/1.1" 200 3256
INFO 2019-04-21 20:57:51,956 basehttp 124 "GET /register/ HTTP/1.1" 200 5287
INFO 2019-04-21 20:57:52,005 basehttp 124 "GET /image_codes/687a8d2a-93f8-4d7d-8837-8b6b4536b927/ HTTP/1.1" 200 3266
INFO 2019-04-21 20:57:52,114 basehttp 124 "GET /register/ HTTP/1.1" 200 5287
INFO 2019-04-21 20:57:52,161 basehttp 124 "GET /image_codes/2b09bdfe-ba3d-44da-a5a0-f30db7730fd2/ HTTP/1.1" 200 2773
INFO 2019-04-21 20:57:52,281 basehttp 124 "GET /register/ HTTP/1.1" 200 5287
INFO 2019-04-21 20:57:52,329 basehttp 124 "GET /image_codes/7186bec5-0cb8-49a6-855c-a97c266b7e5d/ HTTP/1.1" 200 2839
INFO 2019-04-21 20:57:52,446 basehttp 124 "GET /register/ HTTP/1.1" 200 5287
INFO 2019-04-21 20:57:52,493 basehttp 124 "GET /image_codes/ce27ee92-9021-4159-830b-a5fef25fe595/ HTTP/1.1" 200 3039
INFO 2019-04-21 20:57:52,600 basehttp 124 "GET /register/ HTTP/1.1" 200 5287
INFO 2019-04-21 20:57:52,645 basehttp 124 "GET /image_codes/e26fccef-0c63-49d5-b554-926357afa95c/ HTTP/1.1" 200 3496
INFO 2019-04-21 20:57:52,752 basehttp 124 "GET /register/ HTTP/1.1" 200 5287
INFO 2019-04-21 20:57:52,797 basehttp 124 "GET /image_codes/cab80496-7b44-435d-8038-75475cae7cab/ HTTP/1.1" 200 3435
INFO 2019-04-21 20:57:54,326 basehttp 124 "GET /usernames/admin1/count/ HTTP/1.1" 200 41
INFO 2019-04-21 20:58:02,247 basehttp 124 "GET /mobiles/13818510751/count/ HTTP/1.1" 200 41
INFO 2019-04-21 20:58:05,070 views 56 284823
INFO 2019-04-21 20:58:05,075 basehttp 124 "GET /mobiles/13818510751/count/ HTTP/1.1" 200 41
INFO 2019-04-21 20:58:05,097 basehttp 124 "GET /sms_codes/13818510751/?image_code=mblo&image_code_id=cab80496-7b44-435d-8038-75475cae7cab HTTP/1.1" 200 29
INFO 2019-04-21 20:58:50,218 basehttp 124 "POST /register/ HTTP/1.1" 302 0
INFO 2019-04-21 20:58:50,227 basehttp 124 "GET / HTTP/1.1" 200 25122
WARNING 2019-04-21 20:58:50,337 base 152 Not Found: /carts/simple/
WARNING 2019-04-21 20:58:50,338 basehttp 124 "GET /carts/simple/ HTTP/1.1" 404 3068
